<sdf version='1.6'>
  <world name='default'>
    <gui fullscreen='0'>
      <camera name='user_camera'>
        <pose frame=''>2.2814 -0.071881 0.872894 0 0.24 3.075</pose>
        <view_controller>orbit</view_controller>
        <projection_type>perspective</projection_type>
      </camera>
    </gui>
    <physics name='default_physics' default='0' type='ode'>
      <simbody>
        <accuracy>0.005</accuracy>
        <max_transient_velocity>0.005</max_transient_velocity>
        <contact>
          <stiffness>1e+08</stiffness>
          <dissipation>20</dissipation>
        </contact>
      </simbody>
      <ode>
        <solver>
          <use_dynamic_moi_rescaling>1</use_dynamic_moi_rescaling>
          <type>quick</type>
          <iters>200</iters>
          <sor>1</sor>
        </solver>
        <constraints>
          <cfm>0</cfm>
          <erp>0.2</erp>
          <contact_max_correcting_vel>100</contact_max_correcting_vel>
          <contact_surface_layer>0</contact_surface_layer>
        </constraints>
      </ode>
      <real_time_update_rate>1000</real_time_update_rate>
      <max_step_size>0.001</max_step_size>
      <real_time_factor>1</real_time_factor>
    </physics>
    <light name='sun' type='directional'>
      <cast_shadows>1</cast_shadows>
      <pose frame=''>0 0 10 0 -0 0</pose>
      <diffuse>0.8 0.8 0.8 1</diffuse>
      <specular>0.2 0.2 0.2 1</specular>
      <attenuation>
        <range>1000</range>
        <constant>0.9</constant>
        <linear>0.01</linear>
        <quadratic>0.001</quadratic>
      </attenuation>
      <direction>-0.5 0.1 -0.9</direction>
    </light>
    <model name='ground_plane'>
      <static>1</static>
      <link name='link'>
        <collision name='collision'>
          <geometry>
            <plane>
              <normal>0 0 1</normal>
              <size>100 100</size>
            </plane>
          </geometry>
          <surface>
            <friction>
              <ode>
                <mu>100</mu>
                <mu2>50</mu2>
              </ode>
              <torsional>
                <ode/>
              </torsional>
            </friction>
            <contact>
              <ode/>
            </contact>
            <bounce/>
          </surface>
          <max_contacts>10</max_contacts>
        </collision>
        <visual name='visual'>
          <cast_shadows>0</cast_shadows>
          <geometry>
            <plane>
              <normal>0 0 1</normal>
              <size>100 100</size>
            </plane>
          </geometry>
          <material>
            <script>
              <uri>file://media/materials/scripts/gazebo.material</uri>
              <name>Gazebo/Grey</name>
            </script>
          </material>
        </visual>
        <self_collide>0</self_collide>
        <kinematic>0</kinematic>
      </link>
    </model>
    <plugin name='vrc_plugin' filename='libVRCPlugin.so'>
      <atlas>
        <model_name>atlas</model_name>
        <pin_link>utorso</pin_link>
      </atlas>
      <drc_vehicle>
        <model_name>golf_cart</model_name>
        <seat_link>chassis</seat_link>
      </drc_vehicle>
      <drc_fire_hose>
        <fire_hose_model>fire_hose</fire_hose_model>
        <coupling_link>coupling</coupling_link>
        <standpipe_model>standpipe</standpipe_model>
        <spout_link>standpipe</spout_link>
        <thread_pitch>-1000</thread_pitch>
        <coupling_relative_pose>1.17038e-05 -0.125623 0.35 -0.0412152 -1.57078 1.61199</coupling_relative_pose>
      </drc_fire_hose>
    </plugin>
    <plugin name='vrc_scoring' filename='libVRCScoringPlugin.so'/>
    <gravity>0 0 -9.81</gravity>
    <magnetic_field>6e-06 2.3e-05 -4.2e-05</magnetic_field>
    <atmosphere type='adiabatic'/>
    <scene>
      <ambient>0.4 0.4 0.4 1</ambient>
      <background>0.7 0.7 0.7 1</background>
      <shadows>1</shadows>
    </scene>
    <spherical_coordinates>
      <surface_model>EARTH_WGS84</surface_model>
      <latitude_deg>0</latitude_deg>
      <longitude_deg>0</longitude_deg>
      <elevation>0</elevation>
      <heading_deg>0</heading_deg>
    </spherical_coordinates>
    <model name='atlas'>
      <link name='pelvis'>
        <pose frame=''>0 0 0 0 -0 0</pose>
        <inertial>
          <pose frame=''>0.01144 0 0.026813 0 -0 0</pose>
          <mass>14.3529</mass>
          <inertia>
            <ixx>0.125569</ixx>
            <ixy>0.0008</ixy>
            <ixz>-0.00050004</ixz>
            <iyy>0.0972056</iyy>
            <iyz>-0.0005</iyz>
            <izz>0.117937</izz>
          </inertia>
        </inertial>
        <collision name='pelvis_collision'>
          <pose frame=''>0.046 0 -0.02 1.5708 -0 0</pose>
          <geometry>
            <cylinder>
              <length>0.06</length>
              <radius>0.11</radius>
            </cylinder>
          </geometry>
          <surface>
            <contact>
              <ode/>
            </contact>
            <friction>
              <ode>
                <mu>0.9</mu>
                <mu2>0.9</mu2>
              </ode>
              <torsional>
                <ode/>
              </torsional>
            </friction>
            <bounce/>
          </surface>
          <max_contacts>10</max_contacts>
        </collision>
        <collision name='pelvis_collision_1'>
          <pose frame=''>-0.03 0 -0.02 1.5708 -0 0</pose>
          <geometry>
            <cylinder>
              <length>0.06</length>
              <radius>0.11</radius>
            </cylinder>
          </geometry>
          <surface>
            <contact>
              <ode/>
            </contact>
            <friction>
              <ode>
                <mu>0.9</mu>
                <mu2>0.9</mu2>
              </ode>
              <torsional>
                <ode/>
              </torsional>
            </friction>
            <bounce/>
          </surface>
          <max_contacts>10</max_contacts>
        </collision>
        <collision name='pelvis_collision_2'>
          <pose frame=''>0.01 0.042 0.09 0 -0 0</pose>
          <geometry>
            <cylinder>
              <length>0.05</length>
              <radius>0.16</radius>
            </cylinder>
          </geometry>
          <surface>
            <contact>
              <ode/>
            </contact>
            <friction>
              <ode>
                <mu>0.9</mu>
                <mu2>0.9</mu2>
              </ode>
              <torsional>
                <ode/>
              </torsional>
            </friction>
            <bounce/>
          </surface>
          <max_contacts>10</max_contacts>
        </collision>
        <collision name='pelvis_collision_3'>
          <pose frame=''>0.01 -0.042 0.09 0 -0 0</pose>
          <geometry>
            <cylinder>
              <length>0.05</length>
              <radius>0.16</radius>
            </cylinder>
          </geometry>
          <surface>
            <contact>
              <ode/>
            </contact>
            <friction>
              <ode>
                <mu>0.9</mu>
                <mu2>0.9</mu2>
              </ode>
              <torsional>
                <ode/>
              </torsional>
            </friction>
            <bounce/>
          </surface>
          <max_contacts>10</max_contacts>
        </collision>
        <collision name='pelvis_collision_4'>
          <pose frame=''>-0.1 0 -0.05 0 -0 0</pose>
          <geometry>
            <box>
              <size>0.1 0.15 0.2</size>
            </box>
          </geometry>
          <surface>
            <contact>
              <ode/>
            </contact>
            <friction>
              <ode>
                <mu>0.9</mu>
                <mu2>0.9</mu2>
              </ode>
              <torsional>
                <ode/>
              </torsional>
            </friction>
            <bounce/>
          </surface>
          <max_contacts>10</max_contacts>
        </collision>
        <visual name='pelvis_visual'>
          <pose frame=''>0 0 0 0 -0 0</pose>
          <geometry>
            <mesh>
              <scale>1 1 1</scale>
              <uri>model://atlas_description/meshes/pelvis.dae</uri>
            </mesh>
          </geometry>
          <material>
            <script>
              <uri>__default__</uri>
              <name>__default__</name>
            </script>
          </material>
        </visual>
        <visual name='pelvis_fixed_joint_lump__imu_link_visual_1'>
          <pose frame=''>0.059915 0 -0.01415 0 -0 0</pose>
          <geometry>
            <box>
              <size>0.01 0.01 0.01</size>
            </box>
          </geometry>
          <material>
            <script>
              <uri>__default__</uri>
              <name>__default__</name>
            </script>
          </material>
        </visual>
        <velocity_decay/>
        <gravity>1</gravity>
        <velocity_decay/>
        <sensor name='imu_sensor' type='imu'>
          <always_on>1</always_on>
          <update_rate>1000</update_rate>
          <imu>
            <angular_velocity>
              <x>
                <noise type='gaussian'>
                  <mean>0</mean>
                  <stddev>0.0002</stddev>
                  <bias_mean>7.5e-06</bias_mean>
                  <bias_stddev>8e-07</bias_stddev>
                </noise>
              </x>
              <y>
                <noise type='gaussian'>
                  <mean>0</mean>
                  <stddev>0.0002</stddev>
                  <bias_mean>7.5e-06</bias_mean>
                  <bias_stddev>8e-07</bias_stddev>
                </noise>
              </y>
              <z>
                <noise type='gaussian'>
                  <mean>0</mean>
                  <stddev>0.0002</stddev>
                  <bias_mean>7.5e-06</bias_mean>
                  <bias_stddev>8e-07</bias_stddev>
                </noise>
              </z>
            </angular_velocity>
            <linear_acceleration>
              <x>
                <noise type='gaussian'>
                  <mean>0</mean>
                  <stddev>0.017</stddev>
                  <bias_mean>0.1</bias_mean>
                  <bias_stddev>0.001</bias_stddev>
                </noise>
              </x>
              <y>
                <noise type='gaussian'>
                  <mean>0</mean>
                  <stddev>0.017</stddev>
                  <bias_mean>0.1</bias_mean>
                  <bias_stddev>0.001</bias_stddev>
                </noise>
              </y>
              <z>
                <noise type='gaussian'>
                  <mean>0</mean>
                  <stddev>0.017</stddev>
                  <bias_mean>0.1</bias_mean>
                  <bias_stddev>0.001</bias_stddev>
                </noise>
              </z>
            </linear_acceleration>
          </imu>
          <pose frame=''>0.059915 0 -0.01415 0 -0 0</pose>
        </sensor>
        <self_collide>0</self_collide>
        <kinematic>0</kinematic>
      </link>
      <link name='ltorso'>
        <pose frame=''>-0.0125 0 0 0 -0 0</pose>
        <inertial>
          <pose frame=''>-0.011298 -3e-06 0.074684 0 -0 0</pose>
          <mass>1.92</mass>
          <inertia>
            <ixx>0.0039092</ixx>
            <ixy>-5.04491e-08</ixy>
            <ixz>-0.000342157</ixz>
            <iyy>0.00341694</iyy>
            <iyz>4.87119e-07</iyz>
            <izz>0.00174492</izz>
          </inertia>
        </inertial>
        <visual name='ltorso_visual'>
          <pose frame=''>0 0 0 0 -0 0</pose>
          <geometry>
            <mesh>
              <scale>1 1 1</scale>
              <uri>model://atlas_description/meshes/ltorso.dae</uri>
            </mesh>
          </geometry>
          <material>
            <script>
              <uri>__default__</uri>
              <name>__default__</name>
            </script>
          </material>
        </visual>
        <gravity>1</gravity>
        <velocity_decay/>
        <self_collide>0</self_collide>
        <kinematic>0</kinematic>
      </link>
      <joint name='back_lbz' type='revolute'>
        <child>ltorso</child>
        <parent>pelvis</parent>
        <axis>
          <xyz>0 0 1</xyz>
          <limit>
            <lower>-0.610865</lower>
            <upper>0.610865</upper>
            <effort>124.016</effort>
            <velocity>12</velocity>
          </limit>
          <dynamics>
            <damping>10</damping>
            <friction>0</friction>
            <spring_reference>0</spring_reference>
            <spring_stiffness>0</spring_stiffness>
          </dynamics>
          <use_parent_model_frame>1</use_parent_model_frame>
        </axis>
        <physics>
          <ode>
            <implicit_spring_damper>1</implicit_spring_damper>
            <cfm_damping>1</cfm_damping>
            <limit>
              <cfm>0</cfm>
              <erp>0.2</erp>
            </limit>
          </ode>
        </physics>
      </joint>
      <link name='mtorso'>
        <pose frame=''>-0.0125 0 0.09 0 -0 0</pose>
        <inertial>
          <pose frame=''>-0.008163 -0.013125 0.030597 0 -0 0</pose>
          <mass>0.55</mass>
          <inertia>
            <ixx>0.000454181</ixx>
            <ixy>-6.10764e-05</ixy>
            <ixz>3.94009e-05</ixz>
            <iyy>0.000483282</iyy>
            <iyz>5.27463e-05</iyz>
            <izz>0.000444215</izz>
          </inertia>
        </inertial>
        <collision name='mtorso_collision'>
          <pose frame=''>0 0 0 1.5708 -0 0</pose>
          <geometry>
            <cylinder>
              <length>0.03</length>
              <radius>0.017</radius>
            </cylinder>
          </geometry>
          <surface>
            <contact>
              <ode/>
            </contact>
            <friction>
              <ode>
                <mu>0.9</mu>
                <mu2>0.9</mu2>
              </ode>
              <torsional>
                <ode/>
              </torsional>
            </friction>
            <bounce/>
          </surface>
          <max_contacts>10</max_contacts>
        </collision>
        <collision name='mtorso_collision_1'>
          <pose frame=''>0.0285 0 0.05 -3e-06 1.57079 -3e-06</pose>
          <geometry>
            <cylinder>
              <length>0.02</length>
              <radius>0.015</radius>
            </cylinder>
          </geometry>
          <surface>
            <contact>
              <ode/>
            </contact>
            <friction>
              <ode>
                <mu>0.9</mu>
                <mu2>0.9</mu2>
              </ode>
              <torsional>
                <ode/>
              </torsional>
            </friction>
            <bounce/>
          </surface>
          <max_contacts>10</max_contacts>
        </collision>
        <collision name='mtorso_collision_2'>
          <pose frame=''>-0.0285 0 0.05 -3e-06 1.57079 -3e-06</pose>
          <geometry>
            <cylinder>
              <length>0.02</length>
              <radius>0.015</radius>
            </cylinder>
          </geometry>
          <surface>
            <contact>
              <ode/>
            </contact>
            <friction>
              <ode>
                <mu>0.9</mu>
                <mu2>0.9</mu2>
              </ode>
              <torsional>
                <ode/>
              </torsional>
            </friction>
            <bounce/>
          </surface>
          <max_contacts>10</max_contacts>
        </collision>
        <visual name='mtorso_visual'>
          <pose frame=''>0 0 0 0 -0 0</pose>
          <geometry>
            <mesh>
              <scale>1 1 1</scale>
              <uri>model://atlas_description/meshes/mtorso.dae</uri>
            </mesh>
          </geometry>
          <material>
            <script>
              <uri>__default__</uri>
              <name>__default__</name>
            </script>
          </material>
        </visual>
        <gravity>1</gravity>
        <velocity_decay/>
        <self_collide>0</self_collide>
        <kinematic>0</kinematic>
      </link>
      <joint name='back_mby' type='revolute'>
        <child>mtorso</child>
        <parent>ltorso</parent>
        <axis>
          <xyz>0 1 0</xyz>
          <limit>
            <lower>-1.2</lower>
            <upper>1.28</upper>
            <effort>206.843</effort>
            <velocity>12</velocity>
          </limit>
          <dynamics>
            <damping>10</damping>
            <friction>0</friction>
            <spring_reference>0</spring_reference>
            <spring_stiffness>0</spring_stiffness>
          </dynamics>
          <use_parent_model_frame>1</use_parent_model_frame>
        </axis>
        <physics>
          <ode>
            <implicit_spring_damper>1</implicit_spring_damper>
            <cfm_damping>1</cfm_damping>
            <limit>
              <cfm>0</cfm>
              <erp>0.2</erp>
            </limit>
          </ode>
        </physics>
      </joint>
      <link name='utorso'>
        <pose frame=''>-0.0125 0 0.14 0 -0 0</pose>
        <inertial>
          <pose frame=''>0.02 -0.001 0.211 0 -0 0</pose>
          <mass>18.484</mass>
          <inertia>
            <ixx>0.395</ixx>
            <ixy>0</ixy>
            <ixz>0.083</ixz>
            <iyy>1.089</iyy>
            <iyz>-0.003</iyz>
            <izz>0.827</izz>
          </inertia>
        </inertial>
        <collision name='utorso_collision'>
          <pose frame=''>0.0446 0 0.1869 0 -0 0</pose>
          <geometry>
            <box>
              <size>0.3188 0.24 0.3162</size>
            </box>
          </geometry>
          <surface>
            <contact>
              <ode/>
            </contact>
            <friction>
              <ode>
                <mu>0.9</mu>
                <mu2>0.9</mu2>
              </ode>
              <torsional>
                <ode/>
              </torsional>
            </friction>
            <bounce/>
          </surface>
          <max_contacts>10</max_contacts>
        </collision>
        <collision name='utorso_collision_1'>
          <pose frame=''>0.024 0.16 0.18 -0.5236 0 0</pose>
          <geometry>
            <cylinder>
              <length>0.22375</length>
              <radius>0.0363</radius>
            </cylinder>
          </geometry>
          <surface>
            <contact>
              <ode/>
            </contact>
            <friction>
              <ode>
                <mu>0.9</mu>
                <mu2>0.9</mu2>
              </ode>
              <torsional>
                <ode/>
              </torsional>
            </friction>
            <bounce/>
          </surface>
          <max_contacts>10</max_contacts>
        </collision>
        <collision name='utorso_collision_2'>
          <pose frame=''>0.024 -0.16 0.18 0.5236 -0 0</pose>
          <geometry>
            <cylinder>
              <length>0.22375</length>
              <radius>0.0363</radius>
            </cylinder>
          </geometry>
          <surface>
            <contact>
              <ode/>
            </contact>
            <friction>
              <ode>
                <mu>0.9</mu>
                <mu2>0.9</mu2>
              </ode>
              <torsional>
                <ode/>
              </torsional>
            </friction>
            <bounce/>
          </surface>
          <max_contacts>10</max_contacts>
        </collision>
        <visual name='utorso_visual'>
          <pose frame=''>0 0 0 0 -0 0</pose>
          <geometry>
            <mesh>
              <scale>1 1 1</scale>
              <uri>model://atlas_description/meshes/utorso.dae</uri>
            </mesh>
          </geometry>
          <material>
            <script>
              <uri>__default__</uri>
              <name>__default__</name>
            </script>
          </material>
        </visual>
        <gravity>1</gravity>
        <velocity_decay/>
        <self_collide>0</self_collide>
        <kinematic>0</kinematic>
      </link>
      <joint name='back_ubx' type='revolute'>
        <child>utorso</child>
        <parent>mtorso</parent>
        <axis>
          <xyz>1 0 0</xyz>
          <limit>
            <lower>-0.790809</lower>
            <upper>0.790809</upper>
            <effort>94.91</effort>
            <velocity>12</velocity>
          </limit>
          <dynamics>
            <damping>10</damping>
            <friction>0</friction>
            <spring_reference>0</spring_reference>
            <spring_stiffness>0</spring_stiffness>
          </dynamics>
          <use_parent_model_frame>1</use_parent_model_frame>
        </axis>
        <physics>
          <ode>
            <implicit_spring_damper>1</implicit_spring_damper>
            <cfm_damping>1</cfm_damping>
            <limit>
              <cfm>0</cfm>
              <erp>0.2</erp>
            </limit>
          </ode>
        </physics>
      </joint>
      <link name='l_clav'>
        <pose frame=''>0.0115 0.221 0.429 0 -0 0</pose>
        <inertial>
          <pose frame=''>0.014 0.058 0.029 0 -0 0</pose>
          <mass>2.369</mass>
          <inertia>
            <ixx>0.004</ixx>
            <ixy>0.001</ixy>
            <ixz>0</ixz>
            <iyy>0.006</iyy>
            <iyz>0</iyz>
            <izz>0.007</izz>
          </inertia>
        </inertial>
        <collision name='l_clav_collision'>
          <pose frame=''>0 0.0697 0.0261 -3e-06 1.57079 -3e-06</pose>
          <geometry>
            <cylinder>
              <length>0.1525</length>
              <radius>0.045</radius>
            </cylinder>
          </geometry>
          <surface>
            <contact>
              <ode/>
            </contact>
            <friction>
              <ode>
                <mu>0.9</mu>
                <mu2>0.9</mu2>
              </ode>
              <torsional>
                <ode/>
              </torsional>
            </friction>
            <bounce/>
          </surface>
          <max_contacts>10</max_contacts>
        </collision>
        <collision name='l_clav_collision_1'>
          <pose frame=''>-0.005 -0.0074 -0.0538 1.0472 -0 0</pose>
          <geometry>
            <box>
              <size>0.13 0.15 0.05</size>
            </box>
          </geometry>
          <surface>
            <contact>
              <ode/>
            </contact>
            <friction>
              <ode>
                <mu>0.9</mu>
                <mu2>0.9</mu2>
              </ode>
              <torsional>
                <ode/>
              </torsional>
            </friction>
            <bounce/>
          </surface>
          <max_contacts>10</max_contacts>
        </collision>
        <visual name='l_clav_visual'>
          <pose frame=''>0 0 0 1.0472 -0 0</pose>
          <geometry>
            <mesh>
              <scale>1 1 1</scale>
              <uri>model://atlas_description/meshes/l_clav.dae</uri>
            </mesh>
          </geometry>
          <material>
            <script>
              <uri>__default__</uri>
              <name>__default__</name>
            </script>
          </material>
        </visual>
        <gravity>1</gravity>
        <velocity_decay/>
        <self_collide>0</self_collide>
        <kinematic>0</kinematic>
      </link>
      <joint name='l_arm_usy' type='revolute'>
        <child>l_clav</child>
        <parent>utorso</parent>
        <axis>
          <xyz>0 0.5 0.866025</xyz>
          <limit>
            <lower>-1.9635</lower>
            <upper>1.9635</upper>
            <effort>212</effort>
            <velocity>12</velocity>
          </limit>
          <dynamics>
            <damping>1</damping>
            <friction>0</friction>
            <spring_reference>0</spring_reference>
            <spring_stiffness>0</spring_stiffness>
          </dynamics>
          <use_parent_model_frame>1</use_parent_model_frame>
        </axis>
        <physics>
          <ode>
            <implicit_spring_damper>1</implicit_spring_damper>
            <cfm_damping>1</cfm_damping>
            <limit>
              <cfm>0</cfm>
              <erp>0.2</erp>
            </limit>
          </ode>
        </physics>
      </joint>
      <link name='l_scap'>
        <pose frame=''>0.0115 0.296 0.465 0 -0 0</pose>
        <inertial>
          <pose frame=''>-0.002 0.108 0 0 -0 0</pose>
          <mass>2.707</mass>
          <inertia>
            <ixx>0.01</ixx>
            <ixy>0</ixy>
            <ixz>0</ixz>
            <iyy>0.005</iyy>
            <iyz>0</iyz>
            <izz>0.013</izz>
          </inertia>
        </inertial>
        <collision name='l_scap_collision'>
          <pose frame=''>0.001 0.12651 0.01521 1.5708 -0 0</pose>
          <geometry>
            <cylinder>
              <length>0.125</length>
              <radius>0.045</radius>
            </cylinder>
          </geometry>
          <surface>
            <contact>
              <ode/>
            </contact>
            <friction>
              <ode>
                <mu>0.9</mu>
                <mu2>0.9</mu2>
              </ode>
              <torsional>
                <ode/>
              </torsional>
            </friction>
            <bounce/>
          </surface>
          <max_contacts>10</max_contacts>
        </collision>
        <collision name='l_scap_collision_1'>
          <pose frame=''>0.001 0.05 0.016 0 -0 0</pose>
          <geometry>
            <box>
              <size>0.15 0.15 0.06</size>
            </box>
          </geometry>
          <surface>
            <contact>
              <ode/>
            </contact>
            <friction>
              <ode>
                <mu>0.9</mu>
                <mu2>0.9</mu2>
              </ode>
              <torsional>
                <ode/>
              </torsional>
            </friction>
            <bounce/>
          </surface>
          <max_contacts>10</max_contacts>
        </collision>
        <visual name='l_scap_visual'>
          <pose frame=''>0 0 0 0 -0 0</pose>
          <geometry>
            <mesh>
              <scale>1 1 1</scale>
              <uri>model://atlas_description/meshes/l_scap.dae</uri>
            </mesh>
          </geometry>
          <material>
            <script>
              <uri>__default__</uri>
              <name>__default__</name>
            </script>
          </material>
        </visual>
        <gravity>1</gravity>
        <velocity_decay/>
        <self_collide>0</self_collide>
        <kinematic>0</kinematic>
      </link>
      <joint name='l_arm_shx' type='revolute'>
        <child>l_scap</child>
        <parent>l_clav</parent>
        <axis>
          <xyz>1 0 0</xyz>
          <limit>
            <lower>-1.39626</lower>
            <upper>1.74533</upper>
            <effort>170</effort>
            <velocity>12</velocity>
          </limit>
          <dynamics>
            <damping>1</damping>
            <friction>0</friction>
            <spring_reference>0</spring_reference>
            <spring_stiffness>0</spring_stiffness>
          </dynamics>
          <use_parent_model_frame>1</use_parent_model_frame>
        </axis>
        <physics>
          <ode>
            <implicit_spring_damper>1</implicit_spring_damper>
            <cfm_damping>1</cfm_damping>
            <limit>
              <cfm>0</cfm>
              <erp>0.2</erp>
            </limit>
          </ode>
        </physics>
      </joint>
      <link name='l_uarm'>
        <pose frame=''>0.0115 0.481 0.465 0 -0 0</pose>
        <inertial>
          <pose frame=''>0.007 0.114 0.008 0 -0 0</pose>
          <mass>1.881</mass>
          <inertia>
            <ixx>0.002</ixx>
            <ixy>0</ixy>
            <ixz>0</ixz>
            <iyy>0.003</iyy>
            <iyz>0</iyz>
            <izz>0.003</izz>
          </inertia>
        </inertial>
        <collision name='l_uarm_collision'>
          <pose frame=''>0.001 0.111 0 3.14159 1.57079 3.14159</pose>
          <geometry>
            <cylinder>
              <length>0.125</length>
              <radius>0.045</radius>
            </cylinder>
          </geometry>
          <surface>
            <contact>
              <ode/>
            </contact>
            <friction>
              <ode>
                <mu>0.9</mu>
                <mu2>0.9</mu2>
              </ode>
              <torsional>
                <ode/>
              </torsional>
            </friction>
            <bounce/>
          </surface>
          <max_contacts>10</max_contacts>
        </collision>
        <collision name='l_uarm_collision_1'>
          <pose frame=''>0.001 0.043 0.01 -3e-06 1.57079 -3e-06</pose>
          <geometry>
            <box>
              <size>0.04 0.07 0.13</size>
            </box>
          </geometry>
          <surface>
            <contact>
              <ode/>
            </contact>
            <friction>
              <ode>
                <mu>0.9</mu>
                <mu2>0.9</mu2>
              </ode>
              <torsional>
                <ode/>
              </torsional>
            </friction>
            <bounce/>
          </surface>
          <max_contacts>10</max_contacts>
        </collision>
        <visual name='l_uarm_visual'>
          <pose frame=''>0 0 0 0 -0 0</pose>
          <geometry>
            <mesh>
              <scale>1 1 1</scale>
              <uri>model://atlas_description/meshes/l_uarm.dae</uri>
            </mesh>
          </geometry>
          <material>
            <script>
              <uri>__default__</uri>
              <name>__default__</name>
            </script>
          </material>
        </visual>
        <gravity>1</gravity>
        <velocity_decay/>
        <self_collide>0</self_collide>
        <kinematic>0</kinematic>
      </link>
      <joint name='l_arm_ely' type='revolute'>
        <child>l_uarm</child>
        <parent>l_scap</parent>
        <axis>
          <xyz>0 1 0</xyz>
          <limit>
            <lower>0</lower>
            <upper>3.14159</upper>
            <effort>114</effort>
            <velocity>12</velocity>
          </limit>
          <dynamics>
            <damping>1</damping>
            <friction>0</friction>
            <spring_reference>0</spring_reference>
            <spring_stiffness>0</spring_stiffness>
          </dynamics>
          <use_parent_model_frame>1</use_parent_model_frame>
        </axis>
        <physics>
          <ode>
            <implicit_spring_damper>1</implicit_spring_damper>
            <cfm_damping>1</cfm_damping>
            <limit>
              <cfm>0</cfm>
              <erp>0.2</erp>
            </limit>
          </ode>
        </physics>
      </joint>
      <link name='l_larm'>
        <pose frame=''>0.0115 0.602 0.478 0 -0 0</pose>
        <inertial>
          <pose frame=''>-0.003 0.099 -0.014 0 -0 0</pose>
          <mass>2.148</mass>
          <inertia>
            <ixx>0.005</ixx>
            <ixy>0</ixy>
            <ixz>0</ixz>
            <iyy>0.003</iyy>
            <iyz>0</iyz>
            <izz>0.006</izz>
          </inertia>
        </inertial>
        <collision name='l_larm_collision'>
          <pose frame=''>0.001 0.127 0 1.5708 -0 0</pose>
          <geometry>
            <cylinder>
              <length>0.125</length>
              <radius>0.045</radius>
            </cylinder>
          </geometry>
          <surface>
            <contact>
              <ode/>
            </contact>
            <friction>
              <ode>
                <mu>0.9</mu>
                <mu2>0.9</mu2>
              </ode>
              <torsional>
                <ode/>
              </torsional>
            </friction>
            <bounce/>
          </surface>
          <max_contacts>10</max_contacts>
        </collision>
        <collision name='l_larm_collision_1'>
          <pose frame=''>0.001 0.051 0 0 -0 0</pose>
          <geometry>
            <box>
              <size>0.135 0.15 0.06</size>
            </box>
          </geometry>
          <surface>
            <contact>
              <ode/>
            </contact>
            <friction>
              <ode>
                <mu>0.9</mu>
                <mu2>0.9</mu2>
              </ode>
              <torsional>
                <ode/>
              </torsional>
            </friction>
            <bounce/>
          </surface>
          <max_contacts>10</max_contacts>
        </collision>
        <visual name='l_larm_visual'>
          <pose frame=''>0 0 0 0 -0 0</pose>
          <geometry>
            <mesh>
              <scale>1 1 1</scale>
              <uri>model://atlas_description/meshes/l_larm.dae</uri>
            </mesh>
          </geometry>
          <material>
            <script>
              <uri>__default__</uri>
              <name>__default__</name>
            </script>
          </material>
        </visual>
        <gravity>1</gravity>
        <velocity_decay/>
        <self_collide>0</self_collide>
        <kinematic>0</kinematic>
      </link>
      <joint name='l_arm_elx' type='revolute'>
        <child>l_larm</child>
        <parent>l_uarm</parent>
        <axis>
          <xyz>1 0 0</xyz>
          <limit>
            <lower>0</lower>
            <upper>2.35619</upper>
            <effort>114</effort>
            <velocity>12</velocity>
          </limit>
          <dynamics>
            <damping>1</damping>
            <friction>0</friction>
            <spring_reference>0</spring_reference>
            <spring_stiffness>0</spring_stiffness>
          </dynamics>
          <use_parent_model_frame>1</use_parent_model_frame>
        </axis>
        <physics>
          <ode>
            <implicit_spring_damper>1</implicit_spring_damper>
            <cfm_damping>1</cfm_damping>
            <limit>
              <cfm>0</cfm>
              <erp>0.2</erp>
            </limit>
          </ode>
        </physics>
      </joint>
      <link name='l_farm'>
        <pose frame=''>0.0115 0.79 0.465 0 -0 0</pose>
        <inertial>
          <pose frame=''>0 0.041 0 0 -0 0</pose>
          <mass>0.981</mass>
          <inertia>
            <ixx>0.003</ixx>
            <ixy>0</ixy>
            <ixz>0</ixz>
            <iyy>0.001</iyy>
            <iyz>0</iyz>
            <izz>0.003</izz>
          </inertia>
        </inertial>
        <collision name='l_farm_collision'>
          <pose frame=''>0 0.065 0.004 3.14159 1.57079 3.14159</pose>
          <geometry>
            <cylinder>
              <length>0.125</length>
              <radius>0.045</radius>
            </cylinder>
          </geometry>
          <surface>
            <contact>
              <ode/>
            </contact>
            <friction>
              <ode>
                <mu>0.9</mu>
                <mu2>0.9</mu2>
              </ode>
              <torsional>
                <ode/>
              </torsional>
            </friction>
            <bounce/>
          </surface>
          <max_contacts>10</max_contacts>
        </collision>
        <collision name='l_farm_collision_1'>
          <pose frame=''>0.001 0.015 -0.002 0 -0 0</pose>
          <geometry>
            <box>
              <size>0.135 0.1 0.045</size>
            </box>
          </geometry>
          <surface>
            <contact>
              <ode/>
            </contact>
            <friction>
              <ode>
                <mu>0.9</mu>
                <mu2>0.9</mu2>
              </ode>
              <torsional>
                <ode/>
              </torsional>
            </friction>
            <bounce/>
          </surface>
          <max_contacts>10</max_contacts>
        </collision>
        <visual name='l_farm_visual'>
          <pose frame=''>0 -0.06 0 0 -0 0</pose>
          <geometry>
            <mesh>
              <scale>1 1 1</scale>
              <uri>model://atlas_description/meshes/l_farm.dae</uri>
            </mesh>
          </geometry>
          <material>
            <script>
              <uri>__default__</uri>
              <name>__default__</name>
            </script>
          </material>
        </visual>
        <gravity>1</gravity>
        <velocity_decay/>
        <self_collide>0</self_collide>
        <kinematic>0</kinematic>
      </link>
      <joint name='l_arm_uwy' type='revolute'>
        <child>l_farm</child>
        <parent>l_larm</parent>
        <axis>
          <xyz>0 1 0</xyz>
          <limit>
            <lower>-1.571</lower>
            <upper>1.571</upper>
            <effort>114</effort>
            <velocity>12</velocity>
          </limit>
          <dynamics>
            <damping>1</damping>
            <friction>0</friction>
            <spring_reference>0</spring_reference>
            <spring_stiffness>0</spring_stiffness>
          </dynamics>
          <use_parent_model_frame>1</use_parent_model_frame>
        </axis>
        <physics>
          <ode>
            <implicit_spring_damper>1</implicit_spring_damper>
            <cfm_damping>1</cfm_damping>
            <limit>
              <cfm>0</cfm>
              <erp>0.2</erp>
            </limit>
          </ode>
        </physics>
      </joint>
      <link name='l_hand'>
        <pose frame=''>0.0115 0.848 0.465 0 -0 0</pose>
        <inertial>
          <pose frame=''>0 0.093 0 0 -0 0</pose>
          <mass>2.263</mass>
          <inertia>
            <ixx>0.01</ixx>
            <ixy>0</ixy>
            <ixz>0</ixz>
            <iyy>0.002</iyy>
            <iyz>0</iyz>
            <izz>0.01</izz>
          </inertia>
        </inertial>
        <collision name='l_hand_collision'>
          <pose frame=''>0.001 0.1 0.01 1.5708 -0 0</pose>
          <geometry>
            <cylinder>
              <length>0.05</length>
              <radius>0.03</radius>
            </cylinder>
          </geometry>
          <surface>
            <contact>
              <ode/>
            </contact>
            <friction>
              <ode>
                <mu>0.9</mu>
                <mu2>0.9</mu2>
              </ode>
              <torsional>
                <ode/>
              </torsional>
            </friction>
            <bounce/>
          </surface>
          <max_contacts>10</max_contacts>
        </collision>
        <collision name='l_hand_collision_1'>
          <pose frame=''>0.001 0.05 0.01 0 -0 0</pose>
          <geometry>
            <box>
              <size>0.13 0.09 0.07</size>
            </box>
          </geometry>
          <surface>
            <contact>
              <ode/>
            </contact>
            <friction>
              <ode>
                <mu>0.9</mu>
                <mu2>0.9</mu2>
              </ode>
              <torsional>
                <ode/>
              </torsional>
            </friction>
            <bounce/>
          </surface>
          <max_contacts>10</max_contacts>
        </collision>
        <visual name='l_hand_visual'>
          <pose frame=''>0 0 0 0 -0 0</pose>
          <geometry>
            <mesh>
              <scale>1 1 1</scale>
              <uri>model://atlas_description/meshes/l_hand.dae</uri>
            </mesh>
          </geometry>
          <material>
            <script>
              <uri>__default__</uri>
              <name>__default__</name>
            </script>
          </material>
        </visual>
        <gravity>1</gravity>
        <velocity_decay/>
        <self_collide>0</self_collide>
        <kinematic>0</kinematic>
      </link>
      <joint name='l_arm_mwx' type='revolute'>
        <child>l_hand</child>
        <parent>l_farm</parent>
        <axis>
          <xyz>1 0 0</xyz>
          <limit>
            <lower>-0.436</lower>
            <upper>1.571</upper>
            <effort>60</effort>
            <velocity>12</velocity>
          </limit>
          <dynamics>
            <damping>1</damping>
            <friction>0</friction>
            <spring_reference>0</spring_reference>
            <spring_stiffness>0</spring_stiffness>
          </dynamics>
          <use_parent_model_frame>1</use_parent_model_frame>
        </axis>
        <physics>
          <provide_feedback>1</provide_feedback>
          <ode>
            <provide_feedback>1</provide_feedback>
            <limit>
              <cfm>0</cfm>
              <erp>0.2</erp>
            </limit>
            <implicit_spring_damper>1</implicit_spring_damper>
            <cfm_damping>1</cfm_damping>
          </ode>
        </physics>
      </joint>
      <link name='head'>
        <pose frame=''>0.20422 0 0.67796 0 -0 0</pose>
        <inertial>
          <pose frame=''>-0.075494 3.4e-05 0.027741 0 -0 0</pose>
          <mass>1.41991</mass>
          <inertia>
            <ixx>0.00397627</ixx>
            <ixy>-1.51324e-06</ixy>
            <ixz>-0.000892818</ixz>
            <iyy>0.00412515</iyy>
            <iyz>-6.83342e-07</iyz>
            <izz>0.00353178</izz>
          </inertia>
        </inertial>
        <collision name='head_collision'>
          <pose frame=''>-0.0503 0 -0.00195 0 -0 0</pose>
          <geometry>
            <box>
              <size>0.1311 0.12 0.0591</size>
            </box>
          </geometry>
          <surface>
            <contact>
              <ode/>
            </contact>
            <friction>
              <ode>
                <mu>0.9</mu>
                <mu2>0.9</mu2>
              </ode>
              <torsional>
                <ode/>
              </torsional>
            </friction>
            <bounce/>
          </surface>
          <max_contacts>10</max_contacts>
        </collision>
        <collision name='head_collision_1'>
          <pose frame=''>-0.093 0 0.0868 0 -0 0</pose>
          <geometry>
            <box>
              <size>0.0468 0.12 0.1184</size>
            </box>
          </geometry>
          <surface>
            <contact>
              <ode/>
            </contact>
            <friction>
              <ode>
                <mu>0.9</mu>
                <mu2>0.9</mu2>
              </ode>
              <torsional>
                <ode/>
              </torsional>
            </friction>
            <bounce/>
          </surface>
          <max_contacts>10</max_contacts>
        </collision>
        <visual name='head_visual'>
          <pose frame=''>0 0 0 0 -0 0</pose>
          <geometry>
            <mesh>
              <scale>1 1 1</scale>
              <uri>model://multisense_sl_description/meshes/head.dae</uri>
            </mesh>
          </geometry>
          <material>
            <script>
              <uri>__default__</uri>
              <name>__default__</name>
            </script>
          </material>
        </visual>
        <visual name='head_imu_link_visual_1'>
          <pose frame=''>-0.0475 0.035 0 0 -0 0</pose>
          <geometry>
            <box>
              <size>0.01 0.01 0.01</size>
            </box>
          </geometry>
          <material>
            <script>
              <uri>__default__</uri>
              <name>__default__</name>
            </script>
          </material>
        </visual>
        <velocity_decay/>
        <velocity_decay/>
        <sensor name='head_imu_sensor' type='imu'>
          <always_on>1</always_on>
          <update_rate>1000</update_rate>
          <imu>
            <angular_velocity>
              <x>
                <noise type='gaussian'>
                  <mean>0</mean>
                  <stddev>0.0002</stddev>
                  <bias_mean>7.5e-06</bias_mean>
                  <bias_stddev>8e-07</bias_stddev>
                </noise>
              </x>
              <y>
                <noise type='gaussian'>
                  <mean>0</mean>
                  <stddev>0.0002</stddev>
                  <bias_mean>7.5e-06</bias_mean>
                  <bias_stddev>8e-07</bias_stddev>
                </noise>
              </y>
              <z>
                <noise type='gaussian'>
                  <mean>0</mean>
                  <stddev>0.0002</stddev>
                  <bias_mean>7.5e-06</bias_mean>
                  <bias_stddev>8e-07</bias_stddev>
                </noise>
              </z>
            </angular_velocity>
            <linear_acceleration>
              <x>
                <noise type='gaussian'>
                  <mean>0</mean>
                  <stddev>0.017</stddev>
                  <bias_mean>0.1</bias_mean>
                  <bias_stddev>0.001</bias_stddev>
                </noise>
              </x>
              <y>
                <noise type='gaussian'>
                  <mean>0</mean>
                  <stddev>0.017</stddev>
                  <bias_mean>0.1</bias_mean>
                  <bias_stddev>0.001</bias_stddev>
                </noise>
              </y>
              <z>
                <noise type='gaussian'>
                  <mean>0</mean>
                  <stddev>0.017</stddev>
                  <bias_mean>0.1</bias_mean>
                  <bias_stddev>0.001</bias_stddev>
                </noise>
              </z>
            </linear_acceleration>
          </imu>
          <pose frame=''>-0.0475 0.035 0 0 -0 0</pose>
        </sensor>
        <gravity>1</gravity>
        <velocity_decay/>
        <sensor name='stereo_camera' type='multicamera'>
          <update_rate>30</update_rate>
          <camera name='left'>
            <horizontal_fov>1.39626</horizontal_fov>
            <image>
              <width>800</width>
              <height>800</height>
              <format>R8G8B8</format>
            </image>
            <clip>
              <near>0.02</near>
              <far>300</far>
            </clip>
            <noise>
              <type>gaussian</type>
              <mean>0</mean>
              <stddev>0.007</stddev>
            </noise>
          </camera>
          <camera name='right'>
            <pose frame=''>0 -0.07 0 0 -0 0</pose>
            <horizontal_fov>1.39626</horizontal_fov>
            <image>
              <width>800</width>
              <height>800</height>
              <format>R8G8B8</format>
            </image>
            <clip>
              <near>0.02</near>
              <far>300</far>
            </clip>
            <noise>
              <type>gaussian</type>
              <mean>0</mean>
              <stddev>0.007</stddev>
            </noise>
          </camera>
          <plugin name='stereo_camera_controller' filename='libgazebo_ros_multicamera.so'>
            <alwaysOn>true</alwaysOn>
            <updateRate>0.0</updateRate>
            <cameraName>multisense_sl</cameraName>
            <imageTopicName>image_raw</imageTopicName>
            <cameraInfoTopicName>camera_info</cameraInfoTopicName>
            <frameName>left_camera_optical_frame</frameName>
            <hackBaseline>0.07</hackBaseline>
            <distortionK1>0.0</distortionK1>
            <distortionK2>0.0</distortionK2>
            <distortionK3>0.0</distortionK3>
            <distortionT1>0.0</distortionT1>
            <distortionT2>0.0</distortionT2>
          </plugin>
          <pose frame=''>0 0.035 -0.002 0 -0 0</pose>
        </sensor>
        <self_collide>0</self_collide>
        <kinematic>0</kinematic>
      </link>
      <joint name='neck_ay' type='revolute'>
        <child>head</child>
        <parent>utorso</parent>
        <axis>
          <xyz>0 1 0</xyz>
          <limit>
            <lower>-0.610865</lower>
            <upper>1.13446</upper>
            <effort>5</effort>
            <velocity>12</velocity>
          </limit>
          <dynamics>
            <damping>1</damping>
            <friction>0</friction>
            <spring_reference>0</spring_reference>
            <spring_stiffness>0</spring_stiffness>
          </dynamics>
          <use_parent_model_frame>1</use_parent_model_frame>
        </axis>
        <physics>
          <ode>
            <implicit_spring_damper>1</implicit_spring_damper>
            <cfm_damping>1</cfm_damping>
            <limit>
              <cfm>0</cfm>
              <erp>0.2</erp>
            </limit>
          </ode>
        </physics>
      </joint>
      <link name='hokuyo_link'>
        <pose frame=''>0.15962 0 0.76596 0 -0 0</pose>
        <inertial>
          <pose frame=''>0.032435 0.000408 -0.004178 0 -0 0</pose>
          <mass>0.057664</mass>
          <inertia>
            <ixx>3.8183e-05</ixx>
            <ixy>4.9927e-08</ixy>
            <ixz>1.1003e-05</ixz>
            <iyy>4.3437e-05</iyy>
            <iyz>-9.8165e-09</iyz>
            <izz>4.2686e-05</izz>
          </inertia>
        </inertial>
        <collision name='hokuyo_link_collision'>
          <pose frame=''>0.01885 0 -0.02119 0 -0 0</pose>
          <geometry>
            <box>
              <size>0.08 0.06 0.04238</size>
            </box>
          </geometry>
          <surface>
            <contact>
              <ode/>
            </contact>
            <friction>
              <ode>
                <mu>0.9</mu>
                <mu2>0.9</mu2>
              </ode>
              <torsional>
                <ode/>
              </torsional>
            </friction>
            <bounce/>
          </surface>
          <max_contacts>10</max_contacts>
        </collision>
        <collision name='hokuyo_link_collision_1'>
          <pose frame=''>0.03 0 0.0235 0 -0 0</pose>
          <geometry>
            <cylinder>
              <length>0.047</length>
              <radius>0.024425</radius>
            </cylinder>
          </geometry>
          <surface>
            <contact>
              <ode/>
            </contact>
            <friction>
              <ode>
                <mu>0.9</mu>
                <mu2>0.9</mu2>
              </ode>
              <torsional>
                <ode/>
              </torsional>
            </friction>
            <bounce/>
          </surface>
          <max_contacts>10</max_contacts>
        </collision>
        <visual name='hokuyo_link_visual'>
          <pose frame=''>0.045 -0.026102 -0.083424 -0.314 0 0</pose>
          <geometry>
            <mesh>
              <scale>1 1 1</scale>
              <uri>model://multisense_sl_description/meshes/head_camera.dae</uri>
            </mesh>
          </geometry>
          <material>
            <script>
              <uri>__default__</uri>
              <name>__default__</name>
            </script>
          </material>
        </visual>
        <velocity_decay/>
        <gravity>1</gravity>
        <velocity_decay/>
        <sensor name='head_hokuyo_sensor' type='gpu_ray'>
          <visualize>0</visualize>
          <update_rate>40</update_rate>
          <ray>
            <scan>
              <horizontal>
                <samples>720</samples>
                <resolution>1</resolution>
                <min_angle>-1.5708</min_angle>
                <max_angle>1.5708</max_angle>
              </horizontal>
            </scan>
            <range>
              <min>0.1</min>
              <max>30</max>
              <resolution>0.01</resolution>
            </range>
            <noise>
              <type>gaussian</type>
              <mean>0</mean>
              <stddev>0.01</stddev>
            </noise>
          </ray>
          <plugin name='gazebo_ros_head_hokuyo_controller' filename='libgazebo_ros_gpu_laser.so'>
            <topicName>/laser/scan</topicName>
            <frameName>head_hokuyo_frame</frameName>
          </plugin>
          <pose frame=''>0.03 0 0.015 0 -0 0</pose>
        </sensor>
        <self_collide>0</self_collide>
        <kinematic>0</kinematic>
      </link>
      <joint name='hokuyo_joint' type='revolute'>
        <child>hokuyo_link</child>
        <parent>head</parent>
        <axis>
          <xyz>1 0 0</xyz>
          <limit>
            <lower>-1e+16</lower>
            <upper>1e+16</upper>
          </limit>
          <dynamics>
            <damping>0.01</damping>
            <friction>0</friction>
            <spring_reference>0</spring_reference>
            <spring_stiffness>0</spring_stiffness>
          </dynamics>
          <use_parent_model_frame>1</use_parent_model_frame>
        </axis>
        <physics>
          <ode>
            <implicit_spring_damper>1</implicit_spring_damper>
            <cfm_damping>1</cfm_damping>
            <limit>
              <cfm>0</cfm>
              <erp>0.2</erp>
            </limit>
          </ode>
        </physics>
      </joint>
      <link name='r_clav'>
        <pose frame=''>0.0115 -0.221 0.429 0 -0 0</pose>
        <inertial>
          <pose frame=''>0.014 -0.058 0.029 0 -0 0</pose>
          <mass>2.369</mass>
          <inertia>
            <ixx>0.004</ixx>
            <ixy>-0.001</ixy>
            <ixz>0</ixz>
            <iyy>0.006</iyy>
            <iyz>0</iyz>
            <izz>0.007</izz>
          </inertia>
        </inertial>
        <collision name='r_clav_collision'>
          <pose frame=''>0 -0.0697 0.0261 -3e-06 1.57079 -3e-06</pose>
          <geometry>
            <cylinder>
              <length>0.1525</length>
              <radius>0.045</radius>
            </cylinder>
          </geometry>
          <surface>
            <contact>
              <ode/>
            </contact>
            <friction>
              <ode>
                <mu>0.9</mu>
                <mu2>0.9</mu2>
              </ode>
              <torsional>
                <ode/>
              </torsional>
            </friction>
            <bounce/>
          </surface>
          <max_contacts>10</max_contacts>
        </collision>
        <collision name='r_clav_collision_1'>
          <pose frame=''>-0.005 0.0074 -0.0538 -1.0472 0 0</pose>
          <geometry>
            <box>
              <size>0.13 0.15 0.05</size>
            </box>
          </geometry>
          <surface>
            <contact>
              <ode/>
            </contact>
            <friction>
              <ode>
                <mu>0.9</mu>
                <mu2>0.9</mu2>
              </ode>
              <torsional>
                <ode/>
              </torsional>
            </friction>
            <bounce/>
          </surface>
          <max_contacts>10</max_contacts>
        </collision>
        <visual name='r_clav_visual'>
          <pose frame=''>0 0 0 -1.0472 0 0</pose>
          <geometry>
            <mesh>
              <scale>1 1 1</scale>
              <uri>model://atlas_description/meshes/r_clav.dae</uri>
            </mesh>
          </geometry>
          <material>
            <script>
              <uri>__default__</uri>
              <name>__default__</name>
            </script>
          </material>
        </visual>
        <gravity>1</gravity>
        <velocity_decay/>
        <self_collide>0</self_collide>
        <kinematic>0</kinematic>
      </link>
      <joint name='r_arm_usy' type='revolute'>
        <child>r_clav</child>
        <parent>utorso</parent>
        <axis>
          <xyz>0 0.5 -0.866025</xyz>
          <limit>
            <lower>-1.9635</lower>
            <upper>1.9635</upper>
            <effort>212</effort>
            <velocity>12</velocity>
          </limit>
          <dynamics>
            <damping>1</damping>
            <friction>0</friction>
            <spring_reference>0</spring_reference>
            <spring_stiffness>0</spring_stiffness>
          </dynamics>
          <use_parent_model_frame>1</use_parent_model_frame>
        </axis>
        <physics>
          <ode>
            <implicit_spring_damper>1</implicit_spring_damper>
            <cfm_damping>1</cfm_damping>
            <limit>
              <cfm>0</cfm>
              <erp>0.2</erp>
            </limit>
          </ode>
        </physics>
      </joint>
      <link name='r_scap'>
        <pose frame=''>0.0115 -0.296 0.465 0 -0 0</pose>
        <inertial>
          <pose frame=''>-0.002 -0.108 0 0 -0 0</pose>
          <mass>2.707</mass>
          <inertia>
            <ixx>0.01</ixx>
            <ixy>0</ixy>
            <ixz>0</ixz>
            <iyy>0.005</iyy>
            <iyz>0</iyz>
            <izz>0.013</izz>
          </inertia>
        </inertial>
        <collision name='r_scap_collision'>
          <pose frame=''>0.001 -0.12651 0.01521 1.5708 -0 0</pose>
          <geometry>
            <cylinder>
              <length>0.125</length>
              <radius>0.045</radius>
            </cylinder>
          </geometry>
          <surface>
            <contact>
              <ode/>
            </contact>
            <friction>
              <ode>
                <mu>0.9</mu>
                <mu2>0.9</mu2>
              </ode>
              <torsional>
                <ode/>
              </torsional>
            </friction>
            <bounce/>
          </surface>
          <max_contacts>10</max_contacts>
        </collision>
        <collision name='r_scap_collision_1'>
          <pose frame=''>0.001 -0.05 0.016 0 -0 0</pose>
          <geometry>
            <box>
              <size>0.15 0.15 0.06</size>
            </box>
          </geometry>
          <surface>
            <contact>
              <ode/>
            </contact>
            <friction>
              <ode>
                <mu>0.9</mu>
                <mu2>0.9</mu2>
              </ode>
              <torsional>
                <ode/>
              </torsional>
            </friction>
            <bounce/>
          </surface>
          <max_contacts>10</max_contacts>
        </collision>
        <visual name='r_scap_visual'>
          <pose frame=''>0 0 0 0 -0 0</pose>
          <geometry>
            <mesh>
              <scale>1 1 1</scale>
              <uri>model://atlas_description/meshes/r_scap.dae</uri>
            </mesh>
          </geometry>
          <material>
            <script>
              <uri>__default__</uri>
              <name>__default__</name>
            </script>
          </material>
        </visual>
        <gravity>1</gravity>
        <velocity_decay/>
        <self_collide>0</self_collide>
        <kinematic>0</kinematic>
      </link>
      <joint name='r_arm_shx' type='revolute'>
        <child>r_scap</child>
        <parent>r_clav</parent>
        <axis>
          <xyz>1 0 0</xyz>
          <limit>
            <lower>-1.74533</lower>
            <upper>1.39626</upper>
            <effort>170</effort>
            <velocity>12</velocity>
          </limit>
          <dynamics>
            <damping>1</damping>
            <friction>0</friction>
            <spring_reference>0</spring_reference>
            <spring_stiffness>0</spring_stiffness>
          </dynamics>
          <use_parent_model_frame>1</use_parent_model_frame>
        </axis>
        <physics>
          <ode>
            <implicit_spring_damper>1</implicit_spring_damper>
            <cfm_damping>1</cfm_damping>
            <limit>
              <cfm>0</cfm>
              <erp>0.2</erp>
            </limit>
          </ode>
        </physics>
      </joint>
      <link name='r_uarm'>
        <pose frame=''>0.0115 -0.481 0.465 0 -0 0</pose>
        <inertial>
          <pose frame=''>0.007 -0.114 0.008 0 -0 0</pose>
          <mass>1.881</mass>
          <inertia>
            <ixx>0.002</ixx>
            <ixy>0</ixy>
            <ixz>0</ixz>
            <iyy>0.003</iyy>
            <iyz>0</iyz>
            <izz>0.003</izz>
          </inertia>
        </inertial>
        <collision name='r_uarm_collision'>
          <pose frame=''>0.001 -0.111 0 3.14159 1.57079 3.14159</pose>
          <geometry>
            <cylinder>
              <length>0.125</length>
              <radius>0.045</radius>
            </cylinder>
          </geometry>
          <surface>
            <contact>
              <ode/>
            </contact>
            <friction>
              <ode>
                <mu>0.9</mu>
                <mu2>0.9</mu2>
              </ode>
              <torsional>
                <ode/>
              </torsional>
            </friction>
            <bounce/>
          </surface>
          <max_contacts>10</max_contacts>
        </collision>
        <collision name='r_uarm_collision_1'>
          <pose frame=''>0.001 -0.043 0.01 -3e-06 1.57079 -3e-06</pose>
          <geometry>
            <box>
              <size>0.04 0.07 0.13</size>
            </box>
          </geometry>
          <surface>
            <contact>
              <ode/>
            </contact>
            <friction>
              <ode>
                <mu>0.9</mu>
                <mu2>0.9</mu2>
              </ode>
              <torsional>
                <ode/>
              </torsional>
            </friction>
            <bounce/>
          </surface>
          <max_contacts>10</max_contacts>
        </collision>
        <visual name='r_uarm_visual'>
          <pose frame=''>0 0 0 0 -0 0</pose>
          <geometry>
            <mesh>
              <scale>1 1 1</scale>
              <uri>model://atlas_description/meshes/r_uarm.dae</uri>
            </mesh>
          </geometry>
          <material>
            <script>
              <uri>__default__</uri>
              <name>__default__</name>
            </script>
          </material>
        </visual>
        <gravity>1</gravity>
        <velocity_decay/>
        <self_collide>0</self_collide>
        <kinematic>0</kinematic>
      </link>
      <joint name='r_arm_ely' type='revolute'>
        <child>r_uarm</child>
        <parent>r_scap</parent>
        <axis>
          <xyz>0 1 0</xyz>
          <limit>
            <lower>0</lower>
            <upper>3.14159</upper>
            <effort>114</effort>
            <velocity>12</velocity>
          </limit>
          <dynamics>
            <damping>1</damping>
            <friction>0</friction>
            <spring_reference>0</spring_reference>
            <spring_stiffness>0</spring_stiffness>
          </dynamics>
          <use_parent_model_frame>1</use_parent_model_frame>
        </axis>
        <physics>
          <ode>
            <implicit_spring_damper>1</implicit_spring_damper>
            <cfm_damping>1</cfm_damping>
            <limit>
              <cfm>0</cfm>
              <erp>0.2</erp>
            </limit>
          </ode>
        </physics>
      </joint>
      <link name='r_larm'>
        <pose frame=''>0.0115 -0.602 0.478 0 -0 0</pose>
        <inertial>
          <pose frame=''>-0.003 -0.099 -0.014 0 -0 0</pose>
          <mass>2.148</mass>
          <inertia>
            <ixx>0.005</ixx>
            <ixy>0</ixy>
            <ixz>0</ixz>
            <iyy>0.003</iyy>
            <iyz>0</iyz>
            <izz>0.006</izz>
          </inertia>
        </inertial>
        <collision name='r_larm_collision'>
          <pose frame=''>0.001 -0.127 0 1.5708 -0 0</pose>
          <geometry>
            <cylinder>
              <length>0.125</length>
              <radius>0.045</radius>
            </cylinder>
          </geometry>
          <surface>
            <contact>
              <ode/>
            </contact>
            <friction>
              <ode>
                <mu>0.9</mu>
                <mu2>0.9</mu2>
              </ode>
              <torsional>
                <ode/>
              </torsional>
            </friction>
            <bounce/>
          </surface>
          <max_contacts>10</max_contacts>
        </collision>
        <collision name='r_larm_collision_1'>
          <pose frame=''>0.001 -0.051 0 0 -0 0</pose>
          <geometry>
            <box>
              <size>0.135 0.15 0.06</size>
            </box>
          </geometry>
          <surface>
            <contact>
              <ode/>
            </contact>
            <friction>
              <ode>
                <mu>0.9</mu>
                <mu2>0.9</mu2>
              </ode>
              <torsional>
                <ode/>
              </torsional>
            </friction>
            <bounce/>
          </surface>
          <max_contacts>10</max_contacts>
        </collision>
        <visual name='r_larm_visual'>
          <pose frame=''>0 0 0 0 -0 0</pose>
          <geometry>
            <mesh>
              <scale>1 1 1</scale>
              <uri>model://atlas_description/meshes/r_larm.dae</uri>
            </mesh>
          </geometry>
          <material>
            <script>
              <uri>__default__</uri>
              <name>__default__</name>
            </script>
          </material>
        </visual>
        <gravity>1</gravity>
        <velocity_decay/>
        <self_collide>0</self_collide>
        <kinematic>0</kinematic>
      </link>
      <joint name='r_arm_elx' type='revolute'>
        <child>r_larm</child>
        <parent>r_uarm</parent>
        <axis>
          <xyz>1 0 0</xyz>
          <limit>
            <lower>-2.35619</lower>
            <upper>0</upper>
            <effort>114</effort>
            <velocity>12</velocity>
          </limit>
          <dynamics>
            <damping>1</damping>
            <friction>0</friction>
            <spring_reference>0</spring_reference>
            <spring_stiffness>0</spring_stiffness>
          </dynamics>
          <use_parent_model_frame>1</use_parent_model_frame>
        </axis>
        <physics>
          <ode>
            <implicit_spring_damper>1</implicit_spring_damper>
            <cfm_damping>1</cfm_damping>
            <limit>
              <cfm>0</cfm>
              <erp>0.2</erp>
            </limit>
          </ode>
        </physics>
      </joint>
      <link name='r_farm'>
        <pose frame=''>0.0115 -0.79 0.465 0 -0 0</pose>
        <inertial>
          <pose frame=''>0 -0.041 0 0 -0 0</pose>
          <mass>0.981</mass>
          <inertia>
            <ixx>0.003</ixx>
            <ixy>0</ixy>
            <ixz>0</ixz>
            <iyy>0.001</iyy>
            <iyz>0</iyz>
            <izz>0.003</izz>
          </inertia>
        </inertial>
        <collision name='r_farm_collision'>
          <pose frame=''>0 -0.065 0.004 3.14159 1.57079 3.14159</pose>
          <geometry>
            <cylinder>
              <length>0.125</length>
              <radius>0.045</radius>
            </cylinder>
          </geometry>
          <surface>
            <contact>
              <ode/>
            </contact>
            <friction>
              <ode>
                <mu>0.9</mu>
                <mu2>0.9</mu2>
              </ode>
              <torsional>
                <ode/>
              </torsional>
            </friction>
            <bounce/>
          </surface>
          <max_contacts>10</max_contacts>
        </collision>
        <collision name='r_farm_collision_1'>
          <pose frame=''>0.001 -0.015 -0.002 0 -0 0</pose>
          <geometry>
            <box>
              <size>0.135 0.1 0.045</size>
            </box>
          </geometry>
          <surface>
            <contact>
              <ode/>
            </contact>
            <friction>
              <ode>
                <mu>0.9</mu>
                <mu2>0.9</mu2>
              </ode>
              <torsional>
                <ode/>
              </torsional>
            </friction>
            <bounce/>
          </surface>
          <max_contacts>10</max_contacts>
        </collision>
        <visual name='r_farm_visual'>
          <pose frame=''>0 0.06 0 0 -0 0</pose>
          <geometry>
            <mesh>
              <scale>1 1 1</scale>
              <uri>model://atlas_description/meshes/r_farm.dae</uri>
            </mesh>
          </geometry>
          <material>
            <script>
              <uri>__default__</uri>
              <name>__default__</name>
            </script>
          </material>
        </visual>
        <gravity>1</gravity>
        <velocity_decay/>
        <self_collide>0</self_collide>
        <kinematic>0</kinematic>
      </link>
      <joint name='r_arm_uwy' type='revolute'>
        <child>r_farm</child>
        <parent>r_larm</parent>
        <axis>
          <xyz>0 1 0</xyz>
          <limit>
            <lower>-1.571</lower>
            <upper>1.571</upper>
            <effort>114</effort>
            <velocity>12</velocity>
          </limit>
          <dynamics>
            <damping>1</damping>
            <friction>0</friction>
            <spring_reference>0</spring_reference>
            <spring_stiffness>0</spring_stiffness>
          </dynamics>
          <use_parent_model_frame>1</use_parent_model_frame>
        </axis>
        <physics>
          <ode>
            <implicit_spring_damper>1</implicit_spring_damper>
            <cfm_damping>1</cfm_damping>
            <limit>
              <cfm>0</cfm>
              <erp>0.2</erp>
            </limit>
          </ode>
        </physics>
      </joint>
      <link name='r_hand'>
        <pose frame=''>0.0115 -0.848 0.465 0 -0 0</pose>
        <inertial>
          <pose frame=''>0 -0.093 0 0 -0 0</pose>
          <mass>2.263</mass>
          <inertia>
            <ixx>0.01</ixx>
            <ixy>0</ixy>
            <ixz>0</ixz>
            <iyy>0.002</iyy>
            <iyz>0</iyz>
            <izz>0.01</izz>
          </inertia>
        </inertial>
        <collision name='r_hand_collision'>
          <pose frame=''>0.001 -0.1 0.01 1.5708 -0 0</pose>
          <geometry>
            <cylinder>
              <length>0.05</length>
              <radius>0.03</radius>
            </cylinder>
          </geometry>
          <surface>
            <contact>
              <ode/>
            </contact>
            <friction>
              <ode>
                <mu>0.9</mu>
                <mu2>0.9</mu2>
              </ode>
              <torsional>
                <ode/>
              </torsional>
            </friction>
            <bounce/>
          </surface>
          <max_contacts>10</max_contacts>
        </collision>
        <collision name='r_hand_collision_1'>
          <pose frame=''>0.001 -0.05 0.01 0 -0 0</pose>
          <geometry>
            <box>
              <size>0.13 0.09 0.07</size>
            </box>
          </geometry>
          <surface>
            <contact>
              <ode/>
            </contact>
            <friction>
              <ode>
                <mu>0.9</mu>
                <mu2>0.9</mu2>
              </ode>
              <torsional>
                <ode/>
              </torsional>
            </friction>
            <bounce/>
          </surface>
          <max_contacts>10</max_contacts>
        </collision>
        <visual name='r_hand_visual'>
          <pose frame=''>0 0 0 0 -0 0</pose>
          <geometry>
            <mesh>
              <scale>1 1 1</scale>
              <uri>model://atlas_description/meshes/r_hand.dae</uri>
            </mesh>
          </geometry>
          <material>
            <script>
              <uri>__default__</uri>
              <name>__default__</name>
            </script>
          </material>
        </visual>
        <gravity>1</gravity>
        <velocity_decay/>
        <self_collide>0</self_collide>
        <kinematic>0</kinematic>
      </link>
      <joint name='r_arm_mwx' type='revolute'>
        <child>r_hand</child>
        <parent>r_farm</parent>
        <axis>
          <xyz>1 0 0</xyz>
          <limit>
            <lower>-1.571</lower>
            <upper>0.436</upper>
            <effort>60</effort>
            <velocity>12</velocity>
          </limit>
          <dynamics>
            <damping>1</damping>
            <friction>0</friction>
            <spring_reference>0</spring_reference>
            <spring_stiffness>0</spring_stiffness>
          </dynamics>
          <use_parent_model_frame>1</use_parent_model_frame>
        </axis>
        <physics>
          <provide_feedback>1</provide_feedback>
          <ode>
            <provide_feedback>1</provide_feedback>
            <limit>
              <cfm>0</cfm>
              <erp>0.2</erp>
            </limit>
            <implicit_spring_damper>1</implicit_spring_damper>
            <cfm_damping>1</cfm_damping>
          </ode>
        </physics>
      </joint>
      <link name='l_uglut'>
        <pose frame=''>0 0.089 0 0 -0 0</pose>
        <inertial>
          <pose frame=''>0.005293 -0.003447 0.00313 0 -0 0</pose>
          <mass>0.5166</mass>
          <inertia>
            <ixx>0.00074276</ixx>
            <ixy>-3.79607e-08</ixy>
            <ixz>-2.79549e-05</ixz>
            <iyy>0.000688179</iyy>
            <iyz>-3.2735e-08</iyz>
            <izz>0.00041242</izz>
          </inertia>
        </inertial>
        <collision name='l_uglut_collision'>
          <pose frame=''>0 0 0 -3e-06 1.57079 -3e-06</pose>
          <geometry>
            <cylinder>
              <length>0.078396</length>
              <radius>0.019096</radius>
            </cylinder>
          </geometry>
          <surface>
            <contact>
              <ode/>
            </contact>
            <friction>
              <ode>
                <mu>0.9</mu>
                <mu2>0.9</mu2>
              </ode>
              <torsional>
                <ode/>
              </torsional>
            </friction>
            <bounce/>
          </surface>
          <max_contacts>10</max_contacts>
        </collision>
        <collision name='l_uglut_collision_1'>
          <pose frame=''>0 0 0 0 -0 0</pose>
          <geometry>
            <cylinder>
              <length>0.080842</length>
              <radius>0.019841</radius>
            </cylinder>
          </geometry>
          <surface>
            <contact>
              <ode/>
            </contact>
            <friction>
              <ode>
                <mu>0.9</mu>
                <mu2>0.9</mu2>
              </ode>
              <torsional>
                <ode/>
              </torsional>
            </friction>
            <bounce/>
          </surface>
          <max_contacts>10</max_contacts>
        </collision>
        <visual name='l_uglut_visual'>
          <pose frame=''>0 0 0 0 -0 0</pose>
          <geometry>
            <mesh>
              <scale>1 1 1</scale>
              <uri>model://atlas_description/meshes/l_uglut.dae</uri>
            </mesh>
          </geometry>
          <material>
            <script>
              <uri>__default__</uri>
              <name>__default__</name>
            </script>
          </material>
        </visual>
        <gravity>1</gravity>
        <velocity_decay/>
        <self_collide>0</self_collide>
        <kinematic>0</kinematic>
      </link>
      <joint name='l_leg_uhz' type='revolute'>
        <child>l_uglut</child>
        <parent>pelvis</parent>
        <axis>
          <xyz>0 0 1</xyz>
          <limit>
            <lower>-0.32</lower>
            <upper>1.14</upper>
            <effort>110</effort>
            <velocity>12</velocity>
          </limit>
          <dynamics>
            <damping>1</damping>
            <friction>0</friction>
            <spring_reference>0</spring_reference>
            <spring_stiffness>0</spring_stiffness>
          </dynamics>
          <use_parent_model_frame>1</use_parent_model_frame>
        </axis>
        <physics>
          <ode>
            <implicit_spring_damper>1</implicit_spring_damper>
            <cfm_damping>1</cfm_damping>
            <limit>
              <cfm>0</cfm>
              <erp>0.2</erp>
            </limit>
          </ode>
        </physics>
      </joint>
      <link name='l_lglut'>
        <pose frame=''>0 0.089 0 0 -0 0</pose>
        <inertial>
          <pose frame=''>0.013334 0.017048 -0.031205 0 -0 0</pose>
          <mass>0.69</mass>
          <inertia>
            <ixx>0.000691326</ixx>
            <ixy>-2.24344e-05</ixy>
            <ixz>2.50508e-06</ixz>
            <iyy>0.00126856</iyy>
            <iyz>0.000137862</iyz>
            <izz>0.00106487</izz>
          </inertia>
        </inertial>
        <collision name='l_lglut_collision'>
          <pose frame=''>0.049968 0.022488 -0.050117 1.5708 -0 0</pose>
          <geometry>
            <cylinder>
              <length>0.060306</length>
              <radius>0.0200969</radius>
            </cylinder>
          </geometry>
          <surface>
            <contact>
              <ode/>
            </contact>
            <friction>
              <ode>
                <mu>0.9</mu>
                <mu2>0.9</mu2>
              </ode>
              <torsional>
                <ode/>
              </torsional>
            </friction>
            <bounce/>
          </surface>
          <max_contacts>10</max_contacts>
        </collision>
        <collision name='l_lglut_collision_1'>
          <pose frame=''>0 0 0 -3e-06 1.57079 -3e-06</pose>
          <geometry>
            <cylinder>
              <length>0.12</length>
              <radius>0.02</radius>
            </cylinder>
          </geometry>
          <surface>
            <contact>
              <ode/>
            </contact>
            <friction>
              <ode>
                <mu>0.9</mu>
                <mu2>0.9</mu2>
              </ode>
              <torsional>
                <ode/>
              </torsional>
            </friction>
            <bounce/>
          </surface>
          <max_contacts>10</max_contacts>
        </collision>
        <visual name='l_lglut_visual'>
          <pose frame=''>0 0 0 0 -0 0</pose>
          <geometry>
            <mesh>
              <scale>1 1 1</scale>
              <uri>model://atlas_description/meshes/l_lglut.dae</uri>
            </mesh>
          </geometry>
          <material>
            <script>
              <uri>__default__</uri>
              <name>__default__</name>
            </script>
          </material>
        </visual>
        <gravity>1</gravity>
        <velocity_decay/>
        <self_collide>0</self_collide>
        <kinematic>0</kinematic>
      </link>
      <joint name='l_leg_mhx' type='revolute'>
        <child>l_lglut</child>
        <parent>l_uglut</parent>
        <axis>
          <xyz>1 0 0</xyz>
          <limit>
            <lower>-0.47</lower>
            <upper>0.495</upper>
            <effort>180</effort>
            <velocity>12</velocity>
          </limit>
          <dynamics>
            <damping>1</damping>
            <friction>0</friction>
            <spring_reference>0</spring_reference>
            <spring_stiffness>0</spring_stiffness>
          </dynamics>
          <use_parent_model_frame>1</use_parent_model_frame>
        </axis>
        <physics>
          <ode>
            <implicit_spring_damper>1</implicit_spring_damper>
            <cfm_damping>1</cfm_damping>
            <limit>
              <cfm>0</cfm>
              <erp>0.2</erp>
            </limit>
          </ode>
        </physics>
      </joint>
      <link name='l_uleg'>
        <pose frame=''>0.05 0.089 -0.05 0 -0 0</pose>
        <inertial>
          <pose frame=''>0 0 -0.21 0 -0 0</pose>
          <mass>7.34</mass>
          <inertia>
            <ixx>0.09</ixx>
            <ixy>0</ixy>
            <ixz>0</ixz>
            <iyy>0.09</iyy>
            <iyz>0</iyz>
            <izz>0.02</izz>
          </inertia>
        </inertial>
        <collision name='l_uleg_collision'>
          <pose frame=''>-0.0179 0.02085 -0.13 0 -0 0</pose>
          <geometry>
            <cylinder>
              <length>0.1</length>
              <radius>0.1</radius>
            </cylinder>
          </geometry>
          <surface>
            <contact>
              <ode/>
            </contact>
            <friction>
              <ode>
                <mu>0.9</mu>
                <mu2>0.9</mu2>
              </ode>
              <torsional>
                <ode/>
              </torsional>
            </friction>
            <bounce/>
          </surface>
          <max_contacts>10</max_contacts>
        </collision>
        <collision name='l_uleg_collision_1'>
          <pose frame=''>-0.03 0.01 -0.23 0 -0.3 0</pose>
          <geometry>
            <cylinder>
              <length>0.15</length>
              <radius>0.07</radius>
            </cylinder>
          </geometry>
          <surface>
            <contact>
              <ode/>
            </contact>
            <friction>
              <ode>
                <mu>0.9</mu>
                <mu2>0.9</mu2>
              </ode>
              <torsional>
                <ode/>
              </torsional>
            </friction>
            <bounce/>
          </surface>
          <max_contacts>10</max_contacts>
        </collision>
        <collision name='l_uleg_collision_2'>
          <pose frame=''>-0.005 0.01 -0.23 0 0.3 0</pose>
          <geometry>
            <cylinder>
              <length>0.15</length>
              <radius>0.07</radius>
            </cylinder>
          </geometry>
          <surface>
            <contact>
              <ode/>
            </contact>
            <friction>
              <ode>
                <mu>0.9</mu>
                <mu2>0.9</mu2>
              </ode>
              <torsional>
                <ode/>
              </torsional>
            </friction>
            <bounce/>
          </surface>
          <max_contacts>10</max_contacts>
        </collision>
        <collision name='l_uleg_collision_3'>
          <pose frame=''>-0.02 0.03 -0.23 -0.25 0 0</pose>
          <geometry>
            <cylinder>
              <length>0.15</length>
              <radius>0.07</radius>
            </cylinder>
          </geometry>
          <surface>
            <contact>
              <ode/>
            </contact>
            <friction>
              <ode>
                <mu>0.9</mu>
                <mu2>0.9</mu2>
              </ode>
              <torsional>
                <ode/>
              </torsional>
            </friction>
            <bounce/>
          </surface>
          <max_contacts>10</max_contacts>
        </collision>
        <visual name='l_uleg_visual'>
          <pose frame=''>0 0 0 0 -0 0</pose>
          <geometry>
            <mesh>
              <scale>1 1 1</scale>
              <uri>model://atlas_description/meshes/l_uleg.dae</uri>
            </mesh>
          </geometry>
          <material>
            <script>
              <uri>__default__</uri>
              <name>__default__</name>
            </script>
          </material>
        </visual>
        <gravity>1</gravity>
        <velocity_decay/>
        <self_collide>0</self_collide>
        <kinematic>0</kinematic>
      </link>
      <joint name='l_leg_lhy' type='revolute'>
        <child>l_uleg</child>
        <parent>l_lglut</parent>
        <axis>
          <xyz>0 1 0</xyz>
          <limit>
            <lower>-1.75</lower>
            <upper>0.524</upper>
            <effort>260</effort>
            <velocity>12</velocity>
          </limit>
          <dynamics>
            <damping>1</damping>
            <friction>0</friction>
            <spring_reference>0</spring_reference>
            <spring_stiffness>0</spring_stiffness>
          </dynamics>
          <use_parent_model_frame>1</use_parent_model_frame>
        </axis>
        <physics>
          <ode>
            <implicit_spring_damper>1</implicit_spring_damper>
            <cfm_damping>1</cfm_damping>
            <limit>
              <cfm>0</cfm>
              <erp>0.2</erp>
            </limit>
          </ode>
        </physics>
      </joint>
      <link name='l_lleg'>
        <pose frame=''>0 0.089 -0.424 0 -0 0</pose>
        <inertial>
          <pose frame=''>0.001 0 -0.187 0 -0 0</pose>
          <mass>4.367</mass>
          <inertia>
            <ixx>0.077</ixx>
            <ixy>0</ixy>
            <ixz>-0.003</ixz>
            <iyy>0.076</iyy>
            <iyz>0</iyz>
            <izz>0.01</izz>
          </inertia>
        </inertial>
        <collision name='l_lleg_collision'>
          <pose frame=''>0.02 0.00295 -0.18 0 0.1 0</pose>
          <geometry>
            <cylinder>
              <length>0.4</length>
              <radius>0.07</radius>
            </cylinder>
          </geometry>
          <surface>
            <contact>
              <ode/>
            </contact>
            <friction>
              <ode>
                <mu>0.9</mu>
                <mu2>0.9</mu2>
              </ode>
              <torsional>
                <ode/>
              </torsional>
            </friction>
            <bounce/>
          </surface>
          <max_contacts>10</max_contacts>
        </collision>
        <visual name='l_lleg_visual'>
          <pose frame=''>0 0 0 0 -0 0</pose>
          <geometry>
            <mesh>
              <scale>1 1 1</scale>
              <uri>model://atlas_description/meshes/l_lleg.dae</uri>
            </mesh>
          </geometry>
          <material>
            <script>
              <uri>__default__</uri>
              <name>__default__</name>
            </script>
          </material>
        </visual>
        <gravity>1</gravity>
        <velocity_decay/>
        <self_collide>0</self_collide>
        <kinematic>0</kinematic>
      </link>
      <joint name='l_leg_kny' type='revolute'>
        <child>l_lleg</child>
        <parent>l_uleg</parent>
        <axis>
          <xyz>0 1 0</xyz>
          <limit>
            <lower>0</lower>
            <upper>2.45</upper>
            <effort>400</effort>
            <velocity>12</velocity>
          </limit>
          <dynamics>
            <damping>1</damping>
            <friction>0</friction>
            <spring_reference>0</spring_reference>
            <spring_stiffness>0</spring_stiffness>
          </dynamics>
          <use_parent_model_frame>1</use_parent_model_frame>
        </axis>
        <physics>
          <ode>
            <implicit_spring_damper>1</implicit_spring_damper>
            <cfm_damping>1</cfm_damping>
            <limit>
              <cfm>0</cfm>
              <erp>0.2</erp>
            </limit>
          </ode>
        </physics>
      </joint>
      <link name='l_talus'>
        <pose frame=''>0 0.089 -0.846 0 -0 0</pose>
        <inertial>
          <pose frame=''>0 0 0 0 -0 0</pose>
          <mass>0.1</mass>
          <inertia>
            <ixx>1.01674e-05</ixx>
            <ixy>0</ixy>
            <ixz>0</ixz>
            <iyy>8.42775e-06</iyy>
            <iyz>0</iyz>
            <izz>1.30101e-05</izz>
          </inertia>
        </inertial>
        <collision name='l_talus_collision'>
          <pose frame=''>0 0 0 -3e-06 1.57079 -3e-06</pose>
          <geometry>
            <cylinder>
              <length>0.029542</length>
              <radius>0.010181</radius>
            </cylinder>
          </geometry>
          <surface>
            <contact>
              <ode/>
            </contact>
            <friction>
              <ode>
                <mu>0.9</mu>
                <mu2>0.9</mu2>
              </ode>
              <torsional>
                <ode/>
              </torsional>
            </friction>
            <bounce/>
          </surface>
          <max_contacts>10</max_contacts>
        </collision>
        <collision name='l_talus_collision_1'>
          <pose frame=''>0 0 0 1.5708 -0 0</pose>
          <geometry>
            <cylinder>
              <length>0.010059</length>
              <radius>0.010348</radius>
            </cylinder>
          </geometry>
          <surface>
            <contact>
              <ode/>
            </contact>
            <friction>
              <ode>
                <mu>0.9</mu>
                <mu2>0.9</mu2>
              </ode>
              <torsional>
                <ode/>
              </torsional>
            </friction>
            <bounce/>
          </surface>
          <max_contacts>10</max_contacts>
        </collision>
        <visual name='l_talus_visual'>
          <pose frame=''>0 0 0 0 -0 0</pose>
          <geometry>
            <mesh>
              <scale>1 1 1</scale>
              <uri>model://atlas_description/meshes/l_talus.dae</uri>
            </mesh>
          </geometry>
          <material>
            <script>
              <uri>__default__</uri>
              <name>__default__</name>
            </script>
          </material>
        </visual>
        <gravity>1</gravity>
        <velocity_decay/>
        <self_collide>0</self_collide>
        <kinematic>0</kinematic>
      </link>
      <joint name='l_leg_uay' type='revolute'>
        <child>l_talus</child>
        <parent>l_lleg</parent>
        <axis>
          <xyz>0 1 0</xyz>
          <limit>
            <lower>-0.9</lower>
            <upper>0.698</upper>
            <effort>220</effort>
            <velocity>12</velocity>
          </limit>
          <dynamics>
            <damping>1</damping>
            <friction>0</friction>
            <spring_reference>0</spring_reference>
            <spring_stiffness>0</spring_stiffness>
          </dynamics>
          <use_parent_model_frame>1</use_parent_model_frame>
        </axis>
        <physics>
          <ode>
            <implicit_spring_damper>1</implicit_spring_damper>
            <cfm_damping>1</cfm_damping>
            <limit>
              <cfm>0</cfm>
              <erp>0.2</erp>
            </limit>
          </ode>
        </physics>
      </joint>
      <link name='l_foot'>
        <pose frame=''>0 0.089 -0.846 0 -0 0</pose>
        <inertial>
          <pose frame=''>0.027 0 -0.067 0 -0 0</pose>
          <mass>1.634</mass>
          <inertia>
            <ixx>0.002</ixx>
            <ixy>0</ixy>
            <ixz>0</ixz>
            <iyy>0.007</iyy>
            <iyz>0</iyz>
            <izz>0.008</izz>
          </inertia>
        </inertial>
        <collision name='l_foot_collision'>
          <pose frame=''>0.048 0 -0.056119 0 -0 0</pose>
          <geometry>
            <box>
              <size>0.26 0.124887 0.05</size>
            </box>
          </geometry>
          <surface>
            <contact>
              <ode>
                <kp>1e+06</kp>
                <kd>100</kd>
                <max_vel>1</max_vel>
                <min_depth>0</min_depth>
              </ode>
            </contact>
            <friction>
              <ode>
                <mu>1.5</mu>
                <mu2>1.5</mu2>
                <fdir1>1 0 0</fdir1>
              </ode>
              <torsional>
                <ode/>
              </torsional>
            </friction>
            <bounce/>
          </surface>
          <max_contacts>10</max_contacts>
        </collision>
        <visual name='l_foot_visual'>
          <pose frame=''>0 0 0 0 -0 0</pose>
          <geometry>
            <mesh>
              <scale>1 1 1</scale>
              <uri>model://atlas_description/meshes/l_foot.dae</uri>
            </mesh>
          </geometry>
          <material>
            <script>
              <uri>__default__</uri>
              <name>__default__</name>
            </script>
          </material>
        </visual>
        <velocity_decay/>
        <gravity>1</gravity>
        <velocity_decay/>
        <sensor name='l_foot_contact_sensor' type='contact'>
          <update_rate>1000</update_rate>
          <always_on>1</always_on>
          <contact>
            <collision>l_foot_collision</collision>
            <topic>/l_foot_contact</topic>
          </contact>
        </sensor>
        <self_collide>0</self_collide>
        <kinematic>0</kinematic>
      </link>
      <joint name='l_leg_lax' type='revolute'>
        <child>l_foot</child>
        <parent>l_talus</parent>
        <axis>
          <xyz>1 0 0</xyz>
          <limit>
            <lower>-0.436</lower>
            <upper>0.436</upper>
            <effort>90</effort>
            <velocity>12</velocity>
          </limit>
          <dynamics>
            <damping>1</damping>
            <friction>0</friction>
            <spring_reference>0</spring_reference>
            <spring_stiffness>0</spring_stiffness>
          </dynamics>
          <use_parent_model_frame>1</use_parent_model_frame>
        </axis>
        <physics>
          <provide_feedback>1</provide_feedback>
          <ode>
            <provide_feedback>1</provide_feedback>
            <implicit_spring_damper>1</implicit_spring_damper>
            <cfm_damping>1</cfm_damping>
            <limit>
              <cfm>0</cfm>
              <erp>0.2</erp>
            </limit>
          </ode>
        </physics>
      </joint>
      <link name='r_uglut'>
        <pose frame=''>0 -0.089 0 0 -0 0</pose>
        <inertial>
          <pose frame=''>0.005293 0.003447 0.00313 0 -0 0</pose>
          <mass>0.5166</mass>
          <inertia>
            <ixx>0.00074276</ixx>
            <ixy>3.79607e-08</ixy>
            <ixz>-2.79549e-05</ixz>
            <iyy>0.000688179</iyy>
            <iyz>3.2735e-08</iyz>
            <izz>0.00041242</izz>
          </inertia>
        </inertial>
        <collision name='r_uglut_collision'>
          <pose frame=''>0 0 0 -3e-06 1.57079 -3e-06</pose>
          <geometry>
            <cylinder>
              <length>0.078396</length>
              <radius>0.019096</radius>
            </cylinder>
          </geometry>
          <surface>
            <contact>
              <ode/>
            </contact>
            <friction>
              <ode>
                <mu>0.9</mu>
                <mu2>0.9</mu2>
              </ode>
              <torsional>
                <ode/>
              </torsional>
            </friction>
            <bounce/>
          </surface>
          <max_contacts>10</max_contacts>
        </collision>
        <collision name='r_uglut_collision_1'>
          <pose frame=''>0 0 0 0 -0 0</pose>
          <geometry>
            <cylinder>
              <length>0.080842</length>
              <radius>0.019841</radius>
            </cylinder>
          </geometry>
          <surface>
            <contact>
              <ode/>
            </contact>
            <friction>
              <ode>
                <mu>0.9</mu>
                <mu2>0.9</mu2>
              </ode>
              <torsional>
                <ode/>
              </torsional>
            </friction>
            <bounce/>
          </surface>
          <max_contacts>10</max_contacts>
        </collision>
        <visual name='r_uglut_visual'>
          <pose frame=''>0 0 0 0 -0 0</pose>
          <geometry>
            <mesh>
              <scale>1 1 1</scale>
              <uri>model://atlas_description/meshes/r_uglut.dae</uri>
            </mesh>
          </geometry>
          <material>
            <script>
              <uri>__default__</uri>
              <name>__default__</name>
            </script>
          </material>
        </visual>
        <gravity>1</gravity>
        <velocity_decay/>
        <self_collide>0</self_collide>
        <kinematic>0</kinematic>
      </link>
      <joint name='r_leg_uhz' type='revolute'>
        <child>r_uglut</child>
        <parent>pelvis</parent>
        <axis>
          <xyz>0 0 1</xyz>
          <limit>
            <lower>-1.14</lower>
            <upper>0.32</upper>
            <effort>110</effort>
            <velocity>12</velocity>
          </limit>
          <dynamics>
            <damping>1</damping>
            <friction>0</friction>
            <spring_reference>0</spring_reference>
            <spring_stiffness>0</spring_stiffness>
          </dynamics>
          <use_parent_model_frame>1</use_parent_model_frame>
        </axis>
        <physics>
          <ode>
            <implicit_spring_damper>1</implicit_spring_damper>
            <cfm_damping>1</cfm_damping>
            <limit>
              <cfm>0</cfm>
              <erp>0.2</erp>
            </limit>
          </ode>
        </physics>
      </joint>
      <link name='r_lglut'>
        <pose frame=''>0 -0.089 0 0 -0 0</pose>
        <inertial>
          <pose frame=''>0.013334 -0.017048 -0.031205 0 -0 0</pose>
          <mass>0.69</mass>
          <inertia>
            <ixx>0.000691326</ixx>
            <ixy>2.24344e-05</ixy>
            <ixz>2.50508e-06</ixz>
            <iyy>0.00126856</iyy>
            <iyz>-0.000137862</iyz>
            <izz>0.00106487</izz>
          </inertia>
        </inertial>
        <collision name='r_lglut_collision'>
          <pose frame=''>0.049968 -0.022488 -0.050117 1.5708 -0 0</pose>
          <geometry>
            <cylinder>
              <length>0.060306</length>
              <radius>0.0200969</radius>
            </cylinder>
          </geometry>
          <surface>
            <contact>
              <ode/>
            </contact>
            <friction>
              <ode>
                <mu>0.9</mu>
                <mu2>0.9</mu2>
              </ode>
              <torsional>
                <ode/>
              </torsional>
            </friction>
            <bounce/>
          </surface>
          <max_contacts>10</max_contacts>
        </collision>
        <collision name='r_lglut_collision_1'>
          <pose frame=''>0 0 0 -3e-06 1.57079 -3e-06</pose>
          <geometry>
            <cylinder>
              <length>0.12</length>
              <radius>0.02</radius>
            </cylinder>
          </geometry>
          <surface>
            <contact>
              <ode/>
            </contact>
            <friction>
              <ode>
                <mu>0.9</mu>
                <mu2>0.9</mu2>
              </ode>
              <torsional>
                <ode/>
              </torsional>
            </friction>
            <bounce/>
          </surface>
          <max_contacts>10</max_contacts>
        </collision>
        <visual name='r_lglut_visual'>
          <pose frame=''>0 0 0 0 -0 0</pose>
          <geometry>
            <mesh>
              <scale>1 1 1</scale>
              <uri>model://atlas_description/meshes/r_lglut.dae</uri>
            </mesh>
          </geometry>
          <material>
            <script>
              <uri>__default__</uri>
              <name>__default__</name>
            </script>
          </material>
        </visual>
        <gravity>1</gravity>
        <velocity_decay/>
        <self_collide>0</self_collide>
        <kinematic>0</kinematic>
      </link>
      <joint name='r_leg_mhx' type='revolute'>
        <child>r_lglut</child>
        <parent>r_uglut</parent>
        <axis>
          <xyz>1 0 0</xyz>
          <limit>
            <lower>-0.495</lower>
            <upper>0.47</upper>
            <effort>180</effort>
            <velocity>12</velocity>
          </limit>
          <dynamics>
            <damping>1</damping>
            <friction>0</friction>
            <spring_reference>0</spring_reference>
            <spring_stiffness>0</spring_stiffness>
          </dynamics>
          <use_parent_model_frame>1</use_parent_model_frame>
        </axis>
        <physics>
          <ode>
            <implicit_spring_damper>1</implicit_spring_damper>
            <cfm_damping>1</cfm_damping>
            <limit>
              <cfm>0</cfm>
              <erp>0.2</erp>
            </limit>
          </ode>
        </physics>
      </joint>
      <link name='r_uleg'>
        <pose frame=''>0.05 -0.089 -0.05 0 -0 0</pose>
        <inertial>
          <pose frame=''>0 0 -0.21 0 -0 0</pose>
          <mass>7.34</mass>
          <inertia>
            <ixx>0.09</ixx>
            <ixy>0</ixy>
            <ixz>0</ixz>
            <iyy>0.09</iyy>
            <iyz>0</iyz>
            <izz>0.02</izz>
          </inertia>
        </inertial>
        <collision name='r_uleg_collision'>
          <pose frame=''>-0.0179 -0.02085 -0.13 0 -0 0</pose>
          <geometry>
            <cylinder>
              <length>0.1</length>
              <radius>0.1</radius>
            </cylinder>
          </geometry>
          <surface>
            <contact>
              <ode/>
            </contact>
            <friction>
              <ode>
                <mu>0.9</mu>
                <mu2>0.9</mu2>
              </ode>
              <torsional>
                <ode/>
              </torsional>
            </friction>
            <bounce/>
          </surface>
          <max_contacts>10</max_contacts>
        </collision>
        <collision name='r_uleg_collision_1'>
          <pose frame=''>-0.03 -0.01 -0.23 0 -0.3 0</pose>
          <geometry>
            <cylinder>
              <length>0.15</length>
              <radius>0.07</radius>
            </cylinder>
          </geometry>
          <surface>
            <contact>
              <ode/>
            </contact>
            <friction>
              <ode>
                <mu>0.9</mu>
                <mu2>0.9</mu2>
              </ode>
              <torsional>
                <ode/>
              </torsional>
            </friction>
            <bounce/>
          </surface>
          <max_contacts>10</max_contacts>
        </collision>
        <collision name='r_uleg_collision_2'>
          <pose frame=''>-0.005 -0.01 -0.23 0 0.3 0</pose>
          <geometry>
            <cylinder>
              <length>0.15</length>
              <radius>0.07</radius>
            </cylinder>
          </geometry>
          <surface>
            <contact>
              <ode/>
            </contact>
            <friction>
              <ode>
                <mu>0.9</mu>
                <mu2>0.9</mu2>
              </ode>
              <torsional>
                <ode/>
              </torsional>
            </friction>
            <bounce/>
          </surface>
          <max_contacts>10</max_contacts>
        </collision>
        <collision name='r_uleg_collision_3'>
          <pose frame=''>-0.02 -0.03 -0.23 0.25 -0 0</pose>
          <geometry>
            <cylinder>
              <length>0.15</length>
              <radius>0.07</radius>
            </cylinder>
          </geometry>
          <surface>
            <contact>
              <ode/>
            </contact>
            <friction>
              <ode>
                <mu>0.9</mu>
                <mu2>0.9</mu2>
              </ode>
              <torsional>
                <ode/>
              </torsional>
            </friction>
            <bounce/>
          </surface>
          <max_contacts>10</max_contacts>
        </collision>
        <visual name='r_uleg_visual'>
          <pose frame=''>0 0 0 0 -0 0</pose>
          <geometry>
            <mesh>
              <scale>1 1 1</scale>
              <uri>model://atlas_description/meshes/r_uleg.dae</uri>
            </mesh>
          </geometry>
          <material>
            <script>
              <uri>__default__</uri>
              <name>__default__</name>
            </script>
          </material>
        </visual>
        <gravity>1</gravity>
        <velocity_decay/>
        <self_collide>0</self_collide>
        <kinematic>0</kinematic>
      </link>
      <joint name='r_leg_lhy' type='revolute'>
        <child>r_uleg</child>
        <parent>r_lglut</parent>
        <axis>
          <xyz>0 1 0</xyz>
          <limit>
            <lower>-1.745</lower>
            <upper>0.524</upper>
            <effort>260</effort>
            <velocity>12</velocity>
          </limit>
          <dynamics>
            <damping>1</damping>
            <friction>0</friction>
            <spring_reference>0</spring_reference>
            <spring_stiffness>0</spring_stiffness>
          </dynamics>
          <use_parent_model_frame>1</use_parent_model_frame>
        </axis>
        <physics>
          <ode>
            <implicit_spring_damper>1</implicit_spring_damper>
            <cfm_damping>1</cfm_damping>
            <limit>
              <cfm>0</cfm>
              <erp>0.2</erp>
            </limit>
          </ode>
        </physics>
      </joint>
      <link name='r_lleg'>
        <pose frame=''>0 -0.089 -0.424 0 -0 0</pose>
        <inertial>
          <pose frame=''>0.001 0 -0.187 0 -0 0</pose>
          <mass>4.367</mass>
          <inertia>
            <ixx>0.077</ixx>
            <ixy>-0</ixy>
            <ixz>-0.003</ixz>
            <iyy>0.076</iyy>
            <iyz>-0</iyz>
            <izz>0.01</izz>
          </inertia>
        </inertial>
        <collision name='r_lleg_collision'>
          <pose frame=''>0.02 -0.00295 -0.18 0 0.1 0</pose>
          <geometry>
            <cylinder>
              <length>0.4</length>
              <radius>0.07</radius>
            </cylinder>
          </geometry>
          <surface>
            <contact>
              <ode/>
            </contact>
            <friction>
              <ode>
                <mu>0.9</mu>
                <mu2>0.9</mu2>
              </ode>
              <torsional>
                <ode/>
              </torsional>
            </friction>
            <bounce/>
          </surface>
          <max_contacts>10</max_contacts>
        </collision>
        <visual name='r_lleg_visual'>
          <pose frame=''>0 0 0 0 -0 0</pose>
          <geometry>
            <mesh>
              <scale>1 1 1</scale>
              <uri>model://atlas_description/meshes/r_lleg.dae</uri>
            </mesh>
          </geometry>
          <material>
            <script>
              <uri>__default__</uri>
              <name>__default__</name>
            </script>
          </material>
        </visual>
        <gravity>1</gravity>
        <velocity_decay/>
        <self_collide>0</self_collide>
        <kinematic>0</kinematic>
      </link>
      <joint name='r_leg_kny' type='revolute'>
        <child>r_lleg</child>
        <parent>r_uleg</parent>
        <axis>
          <xyz>0 1 0</xyz>
          <limit>
            <lower>0</lower>
            <upper>2.45</upper>
            <effort>400</effort>
            <velocity>12</velocity>
          </limit>
          <dynamics>
            <damping>1</damping>
            <friction>0</friction>
            <spring_reference>0</spring_reference>
            <spring_stiffness>0</spring_stiffness>
          </dynamics>
          <use_parent_model_frame>1</use_parent_model_frame>
        </axis>
        <physics>
          <ode>
            <implicit_spring_damper>1</implicit_spring_damper>
            <cfm_damping>1</cfm_damping>
            <limit>
              <cfm>0</cfm>
              <erp>0.2</erp>
            </limit>
          </ode>
        </physics>
      </joint>
      <link name='r_talus'>
        <pose frame=''>0 -0.089 -0.846 0 -0 0</pose>
        <inertial>
          <pose frame=''>0 0 0 0 -0 0</pose>
          <mass>0.1</mass>
          <inertia>
            <ixx>1.01674e-05</ixx>
            <ixy>0</ixy>
            <ixz>0</ixz>
            <iyy>8.42775e-06</iyy>
            <iyz>0</iyz>
            <izz>1.30101e-05</izz>
          </inertia>
        </inertial>
        <collision name='r_talus_collision'>
          <pose frame=''>0 0 0 -3e-06 1.57079 -3e-06</pose>
          <geometry>
            <cylinder>
              <length>0.029542</length>
              <radius>0.010181</radius>
            </cylinder>
          </geometry>
          <surface>
            <contact>
              <ode/>
            </contact>
            <friction>
              <ode>
                <mu>0.9</mu>
                <mu2>0.9</mu2>
              </ode>
              <torsional>
                <ode/>
              </torsional>
            </friction>
            <bounce/>
          </surface>
          <max_contacts>10</max_contacts>
        </collision>
        <collision name='r_talus_collision_1'>
          <pose frame=''>0 0 0 1.5708 -0 0</pose>
          <geometry>
            <cylinder>
              <length>0.010059</length>
              <radius>0.010348</radius>
            </cylinder>
          </geometry>
          <surface>
            <contact>
              <ode/>
            </contact>
            <friction>
              <ode>
                <mu>0.9</mu>
                <mu2>0.9</mu2>
              </ode>
              <torsional>
                <ode/>
              </torsional>
            </friction>
            <bounce/>
          </surface>
          <max_contacts>10</max_contacts>
        </collision>
        <visual name='r_talus_visual'>
          <pose frame=''>0 0 0 0 -0 0</pose>
          <geometry>
            <mesh>
              <scale>1 1 1</scale>
              <uri>model://atlas_description/meshes/r_talus.dae</uri>
            </mesh>
          </geometry>
          <material>
            <script>
              <uri>__default__</uri>
              <name>__default__</name>
            </script>
          </material>
        </visual>
        <gravity>1</gravity>
        <velocity_decay/>
        <self_collide>0</self_collide>
        <kinematic>0</kinematic>
      </link>
      <joint name='r_leg_uay' type='revolute'>
        <child>r_talus</child>
        <parent>r_lleg</parent>
        <axis>
          <xyz>0 1 0</xyz>
          <limit>
            <lower>-0.9</lower>
            <upper>0.698</upper>
            <effort>220</effort>
            <velocity>12</velocity>
          </limit>
          <dynamics>
            <damping>1</damping>
            <friction>0</friction>
            <spring_reference>0</spring_reference>
            <spring_stiffness>0</spring_stiffness>
          </dynamics>
          <use_parent_model_frame>1</use_parent_model_frame>
        </axis>
        <physics>
          <ode>
            <implicit_spring_damper>1</implicit_spring_damper>
            <cfm_damping>1</cfm_damping>
            <limit>
              <cfm>0</cfm>
              <erp>0.2</erp>
            </limit>
          </ode>
        </physics>
      </joint>
      <link name='r_foot'>
        <pose frame=''>0 -0.089 -0.846 0 -0 0</pose>
        <inertial>
          <pose frame=''>0.027 0 -0.067 0 -0 0</pose>
          <mass>1.634</mass>
          <inertia>
            <ixx>0.002</ixx>
            <ixy>0</ixy>
            <ixz>0</ixz>
            <iyy>0.007</iyy>
            <iyz>0</iyz>
            <izz>0.008</izz>
          </inertia>
        </inertial>
        <collision name='r_foot_collision'>
          <pose frame=''>0.048 0 -0.056119 0 -0 0</pose>
          <geometry>
            <box>
              <size>0.26 0.124887 0.05</size>
            </box>
          </geometry>
          <surface>
            <contact>
              <ode>
                <kp>1e+06</kp>
                <kd>100</kd>
                <max_vel>1</max_vel>
                <min_depth>0</min_depth>
              </ode>
            </contact>
            <friction>
              <ode>
                <mu>1.5</mu>
                <mu2>1.5</mu2>
                <fdir1>1 0 0</fdir1>
              </ode>
              <torsional>
                <ode/>
              </torsional>
            </friction>
            <bounce/>
          </surface>
          <max_contacts>10</max_contacts>
        </collision>
        <visual name='r_foot_visual'>
          <pose frame=''>0 0 0 0 -0 0</pose>
          <geometry>
            <mesh>
              <scale>1 1 1</scale>
              <uri>model://atlas_description/meshes/r_foot.dae</uri>
            </mesh>
          </geometry>
          <material>
            <script>
              <uri>__default__</uri>
              <name>__default__</name>
            </script>
          </material>
        </visual>
        <velocity_decay/>
        <gravity>1</gravity>
        <velocity_decay/>
        <sensor name='r_foot_contact_sensor' type='contact'>
          <update_rate>1000</update_rate>
          <always_on>1</always_on>
          <contact>
            <collision>r_foot_collision</collision>
            <topic>/r_foot_contact</topic>
          </contact>
        </sensor>
        <self_collide>0</self_collide>
        <kinematic>0</kinematic>
      </link>
      <joint name='r_leg_lax' type='revolute'>
        <child>r_foot</child>
        <parent>r_talus</parent>
        <axis>
          <xyz>1 0 0</xyz>
          <limit>
            <lower>-0.436</lower>
            <upper>0.436</upper>
            <effort>90</effort>
            <velocity>12</velocity>
          </limit>
          <dynamics>
            <damping>1</damping>
            <friction>0</friction>
            <spring_reference>0</spring_reference>
            <spring_stiffness>0</spring_stiffness>
          </dynamics>
          <use_parent_model_frame>1</use_parent_model_frame>
        </axis>
        <physics>
          <provide_feedback>1</provide_feedback>
          <ode>
            <provide_feedback>1</provide_feedback>
            <implicit_spring_damper>1</implicit_spring_damper>
            <cfm_damping>1</cfm_damping>
            <limit>
              <cfm>0</cfm>
              <erp>0.2</erp>
            </limit>
          </ode>
        </physics>
      </joint>
      <pose frame=''>0 0 0.93 0 -0 0</pose>
      <plugin name='atlas_plugin' filename='libAtlasPlugin.so'/>
      <plugin name='joint_trajectory_plugin' filename='libgazebo_ros_joint_pose_trajectory.so'>
        <topicName>joint_trajectory</topicName>
        <updateRate>1000.0</updateRate>
      </plugin>
      <plugin name='gazebo_ros_p3d' filename='libgazebo_ros_p3d.so'>
        <bodyName>pelvis</bodyName>
        <topicName>/ground_truth_odom</topicName>
        <alwaysOn>true</alwaysOn>
        <updateRate>100.0</updateRate>
      </plugin>
      <plugin name='gazebo_ros_force' filename='libgazebo_ros_force.so'>
        <bodyName>pelvis</bodyName>
        <topicName>/atlas/apply_pelvis_force</topicName>
      </plugin>
      <static>0</static>
      <plugin name='multisense_plugin' filename='libMultiSenseSLPlugin.so'/>
    </model>
    <state world_name='default'>
      <sim_time>58 0</sim_time>
      <real_time>74 445657411</real_time>
      <wall_time>1521239298 8952320</wall_time>
      <iterations>58000</iterations>
      <model name='atlas'>
        <pose frame=''>0.530848 0.060887 0.201099 0.972152 1.55399 -0.668991</pose>
        <scale>1 1 1</scale>
        <link name='head'>
          <pose frame=''>0.494315 -0.622389 0.016082 1.57402 1.55692 -0.050672</pose>
          <velocity>0.00025 0.001096 0.005825 -0.116245 0.012916 -0.012168</velocity>
          <acceleration>1.0091 28.6825 22.2716 -2.2143 1.26975 -2.10915</acceleration>
          <wrench>1.43284 40.7266 31.6236 0 -0 0</wrench>
        </link>
        <link name='hokuyo_link'>
          <pose frame=''>0.488959 -0.710236 0.060678 0.712054 1.55695 -0.056947</pose>
          <velocity>0.000471 0.004793 0.017387 -0.139454 0.011084 -0.036834</velocity>
          <acceleration>-1.10923 2.56969 44.3019 3.09556 -0.373443 -3.12255</acceleration>
          <wrench>-0.063963 0.148179 2.55463 0 -0 0</wrench>
        </link>
        <link name='l_clav'>
          <pose frame=''>0.726119 -0.379703 0.204029 1.97539 1.28234 0.355481</pose>
          <velocity>0.000643 0.000175 0.002309 -0.00833 0.001796 -0.000288</velocity>
          <acceleration>0.632599 0.794547 5.21034 -2.71722 -0.385135 0.529329</acceleration>
          <wrench>1.49863 1.88228 12.3433 0 -0 0</wrench>
        </link>
        <link name='l_farm'>
          <pose frame=''>0.919896 0.049858 0.214698 -2.81878 -0.197778 2.88411</pose>
          <velocity>0.00025 0.000693 -6e-05 0.000336 -3.8e-05 0.000827</velocity>
          <acceleration>0.405767 1.72712 -0.363043 0.635925 1.55141 0.901203</acceleration>
          <wrench>0.398058 1.69431 -0.356145 0 -0 0</wrench>
        </link>
        <link name='l_foot'>
          <pose frame=''>0.709523 0.883931 0.210426 2.63947 1.37976 1.39782</pose>
          <velocity>-0.000136 -5.3e-05 0.000258 -0.002462 -0.00118 0.000497</velocity>
          <acceleration>0.074382 -0.156401 0.248127 2.0143 -1.56318 1.27859</acceleration>
          <wrench>0.121541 -0.255559 0.405439 0 -0 0</wrench>
        </link>
        <link name='l_hand'>
          <pose frame=''>0.930406 0.103969 0.196658 -2.8143 -0.197778 2.88411</pose>
          <velocity>0.000204 0.000707 -4.1e-05 -0.000106 8.7e-05 0.00092</velocity>
          <acceleration>0.134059 1.74762 -0.450033 -2.00008 1.45808 -1.72032</acceleration>
          <wrench>0.303375 3.95486 -1.01842 0 -0 0</wrench>
        </link>
        <link name='l_larm'>
          <pose frame=''>0.882433 -0.128909 0.261087 -2.81878 -0.197855 2.88408</pose>
          <velocity>0.000359 0.000675 -0.000115 0.000967 0.003235 -0.000274</velocity>
          <acceleration>0.725894 1.70922 -0.345824 -1.54927 -1.45976 -2.3005</acceleration>
          <wrench>1.55922 3.6714 -0.74283 0 -0 0</wrench>
        </link>
        <link name='l_lglut'>
          <pose frame=''>0.619619 0.054639 0.202334 0.943904 1.55544 -0.735059</pose>
          <velocity>-0.000103 4e-06 -0.000115 0.000106 -0.00054 4.6e-05</velocity>
          <acceleration>-0.201796 0.268406 0.13844 2.97042 -0.362512 -0.232753</acceleration>
          <wrench>-0.139239 0.1852 0.095524 0 -0 0</wrench>
        </link>
        <link name='l_lleg'>
          <pose frame=''>0.666568 0.476495 0.109261 3.08975 1.32838 1.41235</pose>
          <velocity>-7e-05 -2.2e-05 9.3e-05 0.000165 -0.000573 3.5e-05</velocity>
          <acceleration>0.033091 -0.022824 0.244537 -1.63738 1.3705 -0.978383</acceleration>
          <wrench>0.144508 -0.099671 1.06789 0 -0 0</wrench>
        </link>
        <link name='l_scap'>
          <pose frame=''>0.79714 -0.420129 0.219611 0.669383 1.28234 0.355482</pose>
          <velocity>0.000639 0.000267 0.002518 -0.008604 0.001668 0.000781</velocity>
          <acceleration>0.838742 1.39535 3.36552 2.60418 0.570785 0.838889</acceleration>
          <wrench>2.27047 3.7772 9.11047 0 -0 0</wrench>
        </link>
        <link name='l_talus'>
          <pose frame=''>0.709523 0.883931 0.210426 3.07547 1.37976 1.39782</pose>
          <velocity>-0.000137 -5.2e-05 0.000258 -0.002462 -0.001179 0.000497</velocity>
          <acceleration>0.121672 -0.080207 0.505513 -1.47948 -1.04049 1.73996</acceleration>
          <wrench>0.012167 -0.008021 0.050551 0 -0 0</wrench>
        </link>
        <link name='l_uarm'>
          <pose frame=''>0.849815 -0.24582 0.252267 2.96058 -0.197855 2.88408</pose>
          <velocity>0.000495 0.000571 0.000939 -0.007503 0.005453 0.00146</velocity>
          <acceleration>0.909042 1.78997 -0.001153 -2.18738 0.51926 2.22488</acceleration>
          <wrench>1.70991 3.36693 -0.002169 0 -0 0</wrench>
        </link>
        <link name='l_uglut'>
          <pose frame=''>0.619619 0.054639 0.202334 0.905744 1.55544 -0.735407</pose>
          <velocity>-8e-05 0.000112 -0.000136 0.001319 -0.000904 0.002041</velocity>
          <acceleration>-0.146931 0.611188 0.186207 2.12377 0.106925 -1.7296</acceleration>
          <wrench>-0.075905 0.31574 0.096194 0 -0 0</wrench>
        </link>
        <link name='l_uleg'>
          <pose frame=''>0.625588 0.10383 0.151889 0.051003 1.32436 -1.62944</pose>
          <velocity>-7e-05 -5e-06 -0.000105 0.00037 -0.000575 4.6e-05</velocity>
          <acceleration>-0.07151 0.100786 0.088135 0.804158 0.099982 1.65612</acceleration>
          <wrench>-0.524885 0.739768 0.646908 0 -0 0</wrench>
        </link>
        <link name='ltorso'>
          <pose frame=''>0.530686 0.061016 0.213599 0.986782 1.5536 -0.654335</pose>
          <velocity>-2.5e-05 6.8e-05 -0.000161 0.003821 0.002071 0.002734</velocity>
          <acceleration>0.312888 0.684467 -0.416972 2.79689 -0.054781 0.657028</acceleration>
          <wrench>0.600745 1.31418 -0.800586 0 -0 0</wrench>
        </link>
        <link name='mtorso'>
          <pose frame=''>0.524361 -0.028764 0.214454 0.436634 1.53683 -1.20464</pose>
          <velocity>0.00036 0.000408 -0.000338 -0.009008 0.002691 0.008562</velocity>
          <acceleration>1.11801 1.51764 0.417205 -0.59244 -0.290457 1.99367</acceleration>
          <wrench>0.614908 0.834702 0.229463 0 -0 0</wrench>
        </link>
        <link name='pelvis'>
          <pose frame=''>0.530848 0.060887 0.201099 0.972152 1.55399 -0.668991</pose>
          <velocity>-7.4e-05 2.1e-05 -0.000318 0.003297 -0.002051 0.002315</velocity>
          <acceleration>-2.3e-05 0.701725 -0.360501 2.62986 -0.113182 -0.113384</acceleration>
          <wrench>-0.000335 10.0718 -5.17423 0 -0 0</wrench>
        </link>
        <link name='r_clav'>
          <pose frame=''>0.284802 -0.355926 0.197906 -2.01718 1.30955 2.63829</pose>
          <velocity>0.000643 8.3e-05 0.003145 -0.012528 -0.003728 0.000409</velocity>
          <acceleration>0.719751 1.21921 7.78447 -0.769366 -0.97193 2.32184</acceleration>
          <wrench>1.70509 2.8883 18.4414 0 -0 0</wrench>
        </link>
        <link name='r_farm'>
          <pose frame=''>0.134922 0.091462 0.203513 2.81184 -0.225215 0.15756</pose>
          <velocity>-0.000125 0.000498 -0.000339 0.000873 -0.000203 -0.001486</velocity>
          <acceleration>-0.486679 2.60302 -0.345846 2.59101 -1.14054 -1.08282</acceleration>
          <wrench>-0.477432 2.55356 -0.339275 0 -0 0</wrench>
        </link>
        <link name='r_foot'>
          <pose frame=''>0.433956 0.900211 0.215328 0.331597 1.54321 -1.19985</pose>
          <velocity>-8.4e-05 -0.000172 0.000296 -0.001455 -0.000477 0.001615</velocity>
          <acceleration>0.040922 -0.231974 0.286472 -1.03952 0.23014 -2.96757</acceleration>
          <wrench>0.066867 -0.379045 0.468095 0 -0 0</wrench>
        </link>
        <link name='r_hand'>
          <pose frame=''>0.130454 0.146316 0.185206 2.80569 -0.225215 0.15756</pose>
          <velocity>-3.8e-05 0.000519 -0.000292 0.000274 -0.000315 -0.001626</velocity>
          <acceleration>0.119151 2.57759 -0.55389 2.4998 0.624651 1.01512</acceleration>
          <wrench>0.26964 5.8331 -1.25345 0 -0 0</wrench>
        </link>
        <link name='r_larm'>
          <pose frame=''>0.152785 -0.090064 0.250864 2.8118 -0.22568 0.157724</pose>
          <velocity>-0.000209 0.000483 -0.000453 0.002061 -0.014891 0.003436</velocity>
          <acceleration>-1.04456 2.45634 -0.800201 2.35119 0.010443 -0.260385</acceleration>
          <wrench>-2.24371 5.27621 -1.71883 0 -0 0</wrench>
        </link>
        <link name='r_lglut'>
          <pose frame=''>0.442073 0.067146 0.199865 0.765983 1.5568 -0.795372</pose>
          <velocity>-8.1e-05 -0.000242 -0.00048 0.003131 -0.000293 0.000618</velocity>
          <acceleration>-0.156467 0.10731 -0.496177 -2.13362 0.45156 2.40454</acceleration>
          <wrench>-0.107962 0.074044 -0.342362 0 -0 0</wrench>
        </link>
        <link name='r_lleg'>
          <pose frame=''>0.438896 0.491819 0.109138 3.10293 1.31622 1.54294</pose>
          <velocity>-6.3e-05 -0.000106 5.7e-05 0.000542 -0.000491 -6.6e-05</velocity>
          <acceleration>0.060596 -0.061741 0.248498 -2.27644 0.535351 0.587062</acceleration>
          <wrench>0.264624 -0.269625 1.08519 0 -0 0</wrench>
        </link>
        <link name='r_scap'>
          <pose frame=''>0.209424 -0.388454 0.211365 -0.717665 1.30955 2.63829</pose>
          <velocity>0.000623 0.000198 0.003271 -0.011875 -0.004044 0.003024</velocity>
          <acceleration>-0.20334 2.12229 4.79591 0.491485 1.03176 -2.55628</acceleration>
          <wrench>-0.550441 5.74502 12.9825 0 -0 0</wrench>
        </link>
        <link name='r_talus'>
          <pose frame=''>0.433956 0.900208 0.215331 0.360543 1.54322 -1.20081</pose>
          <velocity>-8.6e-05 -0.000161 0.000288 -0.001438 -0.000453 -8.7e-05</velocity>
          <acceleration>0.167948 -0.073492 0.430467 -1.87454 0.811788 0.341894</acceleration>
          <wrench>0.016795 -0.007349 0.043047 0 -0 0</wrench>
        </link>
        <link name='r_uarm'>
          <pose frame=''>0.173686 -0.20968 0.242788 -2.96643 -0.22568 0.157724</pose>
          <velocity>1.1e-05 0.000438 0.001018 -0.00939 -0.016688 0.000811</velocity>
          <acceleration>-1.22897 2.58967 -0.431671 2.66467 1.21157 -0.409758</acceleration>
          <wrench>-2.31169 4.87116 -0.811973 0 -0 0</wrench>
        </link>
        <link name='r_uglut'>
          <pose frame=''>0.442076 0.067138 0.199862 0.83562 1.55668 -0.805541</pose>
          <velocity>-8.7e-05 -0.000192 -0.00048 0.003501 -0.000295 0.002313</velocity>
          <acceleration>-0.135087 0.378393 -0.554535 -1.92932 0.017773 0.851439</acceleration>
          <wrench>-0.069786 0.195478 -0.286473 0 -0 0</wrench>
        </link>
        <link name='r_uleg'>
          <pose frame=''>0.442093 0.116652 0.149366 0.04094 1.33089 -1.52146</pose>
          <velocity>-0.000106 -0.000133 -0.000323 0.000987 -0.000402 -5.3e-05</velocity>
          <acceleration>-0.113115 0.049772 -0.158861 -1.6708 0.544745 -0.815478</acceleration>
          <wrench>-0.830266 0.36533 -1.16604 0 -0 0</wrench>
        </link>
        <link name='utorso'>
          <pose frame=''>0.520832 -0.078616 0.215993 0.420195 1.53683 -1.20464</pose>
          <velocity>0.00071 0.000405 0.000149 -0.008873 0.002409 -0.000108</velocity>
          <acceleration>0.818395 1.36244 4.84473 0.945241 -1.12291 -1.00629</acceleration>
          <wrench>15.1272 25.1833 89.55 0 -0 0</wrench>
        </link>
      </model>
      <model name='ground_plane'>
        <pose frame=''>0 0 0 0 -0 0</pose>
        <scale>1 1 1</scale>
        <link name='link'>
          <pose frame=''>0 0 0 0 -0 0</pose>
          <velocity>0 0 0 0 -0 0</velocity>
          <acceleration>0 0 0 0 -0 0</acceleration>
          <wrench>0 0 0 0 -0 0</wrench>
        </link>
      </model>
      <light name='sun'>
        <pose frame=''>0 0 10 0 -0 0</pose>
      </light>
    </state>
  </world>
</sdf>
